Workbook

Sheet UCL SS
A1: Retorta League (18/03/2024 a 29/07/2024)
A2: Ranking | B2: Jogadores | C2: Alcunha | D2: Jogos | E2: Vitórias | F2: Derrotas | G2: Win Rate | H2: Fator | I2: Média base | J2: Média ponderada | L2: 45369 | M2: 45376 | N2: 45383 | O2: 45390 | P2: 45397 | Q2: 45404 | R2: 45411 | S2: 45418 | T2: 45425 | U2: 45432 | V2: 45439 | W2: 45446 | X2: 45453 | Y2: 45460 | Z2: 45467 | AA2: 45476 | AB2: 45481 | AC2: 45495 | AD2: 45502
A3: 1 | B3: João Capela | C3: Capela | D3: 19 | E3: 13 | F3: 6 | G3: =E3/D3 -> 0.68421053 | H3: =+_xlfn.XLOOKUP(D3,$B$36:$B$54,$C$36:$C$54) -> 1 | I3: =+E3/D3 -> 0.68421053 | J3: =I3*H3 -> 0.68421053 | L3: L | M3: W | N3: W | O3: W | P3: L | Q3: W | R3: W | S3: W | T3: L | U3: W | V3: W | W3: W | X3: L | Y3: L | Z3: W | AA3: L | AB3: W | AC3: W | AD3: W
A4: 2 | B4: Pedro Vieira | C4: Vieira | D4: 18 | E4: 10 | F4: 8 | G4: =E4/D4 -> 0.55555556 | H4: =+_xlfn.XLOOKUP(D4,$B$36:$B$54,$C$36:$C$54) -> 0.94736842 | I4: =+E4/D4 -> 0.55555556 | J4: =I4*H4 -> 0.52631579 | L4: L | M4: L | O4: L | P4: L | Q4: W | R4: W | S4: L | T4: W | U4: W | V4: W | W4: L | X4: W | Y4: W | Z4: W | AA4: W | AB4: L | AC4: L | AD4: W
A5: 3 | B5: Francisco Campos | C5: Campos | D5: 17 | E5: 9 | F5: 8 | G5: =E5/D5 -> 0.52941176 | H5: =+_xlfn.XLOOKUP(D5,$B$36:$B$54,$C$36:$C$54) -> 0.89473684 | I5: =+E5/D5 -> 0.52941176 | J5: =I5*H5 -> 0.47368421 | L5: W | M5: L | N5: L | O5: W | P5: L | Q5: W | S5: L | T5: L | U5: W | V5: W | W5: L | X5: W | Y5: W | AA5: L | AB5: W | AC5: L | AD5: W
A6: 4 | B6: José Miguel Ferreira | C6: Zé Miguel | D6: 13 | E6: 8 | F6: 5 | G6: =E6/D6 -> 0.61538462 | H6: =+_xlfn.XLOOKUP(D6,$B$36:$B$54,$C$36:$C$54) -> 0.68421053 | I6: =+E6/D6 -> 0.61538462 | J6: =I6*H6 -> 0.42105263 | L6: W | M6: L | N6: L | O6: L | Q6: W | S6: L | T6: W | U6: W | V6: L | W6: W | Y6: W | AA6: W | AB6: W
A7: 4 | B7: Rui Dimas | C7: Dimas | D7: 16 | E7: 8 | F7: 8 | G7: =E7/D7 -> 0.5 | H7: =+_xlfn.XLOOKUP(D7,$B$36:$B$54,$C$36:$C$54) -> 0.84210526 | I7: =+E7/D7 -> 0.5 | J7: =I7*H7 -> 0.42105263 | N7: W | O7: L | P7: L | Q7: L | R7: W | S7: L | T7: W | U7: L | W7: L | X7: W | Y7: W | Z7: W | AA7: W | AB7: L | AC7: W | AD7: L
A8: 4 | B8: Joaquim Torrão | C8: Quim | D8: 19 | E8: 8 | F8: 11 | G8: =E8/D8 -> 0.42105263 | H8: =+_xlfn.XLOOKUP(D8,$B$36:$B$54,$C$36:$C$54) -> 1 | I8: =+E8/D8 -> 0.42105263 | J8: =I8*H8 -> 0.42105263 | L8: L | M8: W | N8: L | O8: W | P8: W | Q8: W | R8: W | S8: L | T8: L | U8: L | V8: L | W8: W | X8: W | Y8: L | Z8: L | AA8: L | AB8: L | AC8: L | AD8: W
A9: 7 | B9: Eduardo Maia | C9: Edu | D9: 15 | E9: 7 | F9: 8 | G9: =E9/D9 -> 0.46666667 | H9: =+_xlfn.XLOOKUP(D9,$B$36:$B$54,$C$36:$C$54) -> 0.78947368 | I9: =+E9/D9 -> 0.46666667 | J9: =I9*H9 -> 0.36842105 | L9: L | M9: W | N9: L | O9: W | P9: W | R9: L | S9: W | T9: L | V9: W | W9: L | X9: L | Y9: L | Z9: L | AA9: W | AB9: W
A10: 8 | B10: Francisco Santos | C10: Xico Santos | D10: 9 | E10: 6 | F10: 3 | G10: =E10/D10 -> 0.66666667 | H10: =+_xlfn.XLOOKUP(D10,$B$36:$B$54,$C$36:$C$54) -> 0.47368421 | I10: =+E10/D10 -> 0.66666667 | J10: =I10*H10 -> 0.31578947 | L10: W | M10: L | N10: W | O10: W | S10: W | T10: W | U10: W | V10: L | AC10: L
A11: 9 | B11: Rui Vaz | C11: Rui Vaz | D11: 9 | E11: 5 | F11: 4 | G11: =E11/D11 -> 0.55555556 | H11: =+_xlfn.XLOOKUP(D11,$B$36:$B$54,$C$36:$C$54) -> 0.47368421 | I11: =+E11/D11 -> 0.55555556 | J11: =I11*H11 -> 0.26315789 | P11: W | Q11: L | R11: L | S11: W | T11: L | V11: W | W11: W | AC11: W | AD11: L
A12: 10 | B12: Guilherme Moura | C12: Gui Moura | D12: 8 | E12: 4 | F12: 4 | G12: =E12/D12 -> 0.5 | H12: =+_xlfn.XLOOKUP(D12,$B$36:$B$54,$C$36:$C$54) -> 0.42105263 | I12: =+E12/D12 -> 0.5 | J12: =I12*H12 -> 0.21052632 | M12: W | P12: W | Q12: L | R12: L | S12: W | U12: L | V12: L | W12: W
A13: 11 | B13: João Santos | C13: Jorginho | D13: 4 | E13: 3 | F13: 1 | G13: =E13/D13 -> 0.75 | H13: =+_xlfn.XLOOKUP(D13,$B$36:$B$54,$C$36:$C$54) -> 0.21052632 | I13: =+E13/D13 -> 0.75 | J13: =I13*H13 -> 0.15789474 | L13: W | AB13: W | AC13: W | AD13: L
A14: 11 | B14: Diogo Azevedo | C14: Dipi | D14: 4 | E14: 3 | F14: 1 | G14: =E14/D14 -> 0.75 | H14: =+_xlfn.XLOOKUP(D14,$B$36:$B$54,$C$36:$C$54) -> 0.21052632 | I14: =+E14/D14 -> 0.75 | J14: =I14*H14 -> 0.15789474 | X14: W | Y14: W | Z14: W | AB14: L
A15: 11 | B15: Tiago Filipe | C15: Tigas | D15: 12 | E15: 3 | F15: 9 | G15: =E15/D15 -> 0.25 | H15: =+_xlfn.XLOOKUP(D15,$B$36:$B$54,$C$36:$C$54) -> 0.63157895 | I15: =+E15/D15 -> 0.25 | J15: =I15*H15 -> 0.15789474 | L15: L | M15: W | N15: W | Q15: L | R15: L | U15: L | V15: L | W15: L | X15: L | Y15: L | AA15: L | AD15: W
A16: 14 | B16: Diogo Duarte | C16: Insua | D16: 4 | E16: 2 | F16: 2 | G16: =E16/D16 -> 0.5 | H16: =+_xlfn.XLOOKUP(D16,$B$36:$B$54,$C$36:$C$54) -> 0.21052632 | I16: =+E16/D16 -> 0.5 | J16: =I16*H16 -> 0.10526316 | X16: L | Z16: W | AC16: W | AD16: L
A17: 14 | B17: Dinis Pontes | C17: Trator | D17: 5 | E17: 2 | F17: 3 | G17: =E17/D17 -> 0.4 | H17: =+_xlfn.XLOOKUP(D17,$B$36:$B$54,$C$36:$C$54) -> 0.26315789 | I17: =+E17/D17 -> 0.4 | J17: =I17*H17 -> 0.10526316 | R17: W | X17: L | Y17: L | AA17: W | AD17: L
A18: 16 | B18: André Amorim | C18: Bolinha | D18: 1 | E18: 1 | F18: 0 | G18: =E18/D18 -> 1 | H18: =+_xlfn.XLOOKUP(D18,$B$36:$B$54,$C$36:$C$54) -> 0.052631579 | I18: =+E18/D18 -> 1 | J18: =I18*H18 -> 0.052631579 | L18: W
A19: 16 | B19: Ricardo Nunes | C19: Nunes | D19: 1 | E19: 1 | F19: 0 | G19: =E19/D19 -> 1 | H19: =+_xlfn.XLOOKUP(D19,$B$36:$B$54,$C$36:$C$54) -> 0.052631579 | I19: =+E19/D19 -> 1 | J19: =I19*H19 -> 0.052631579 | N19: W
A20: 16 | B20: António Moreira | C20: Toni Moreira | D20: 1 | E20: 1 | F20: 0 | G20: =E20/D20 -> 1 | H20: =+_xlfn.XLOOKUP(D20,$B$36:$B$54,$C$36:$C$54) -> 0.052631579 | I20: =+E20/D20 -> 1 | J20: =I20*H20 -> 0.052631579 | T20: W
A21: 16 | B21: Pedro Miranda | C21: Miranda | D21: 2 | E21: 1 | F21: 1 | G21: =E21/D21 -> 0.5 | H21: =+_xlfn.XLOOKUP(D21,$B$36:$B$54,$C$36:$C$54) -> 0.10526316 | I21: =+E21/D21 -> 0.5 | J21: =I21*H21 -> 0.052631579 | P21: W | U21: L
A22: 20 | B22: Bruno Silva | C22: Bruno | D22: 2 | E22: 0 | F22: 2 | G22: =E22/D22 -> 0 | H22: =+_xlfn.XLOOKUP(D22,$B$36:$B$54,$C$36:$C$54) -> 0.10526316 | I22: =+E22/D22 -> 0 | J22: =I22*H22 -> 0 | M22: L | P22: L
A23: 20 | B23: João Órfão | C23: Órfão | D23: 3 | E23: 0 | F23: 3 | G23: =E23/D23 -> 0 | H23: =+_xlfn.XLOOKUP(D23,$B$36:$B$54,$C$36:$C$54) -> 0.15789474 | I23: =+E23/D23 -> 0 | J23: =I23*H23 -> 0 | AA23: L | AB23: L | AC23: L
A24: 20 | B24: Peliteiro | C24: Peli | D24: 1 | E24: 0 | F24: 1 | G24: =E24/D24 -> 0 | H24: =+_xlfn.XLOOKUP(D24,$B$36:$B$54,$C$36:$C$54) -> 0.052631579 | I24: =+E24/D24 -> 0 | J24: =I24*H24 -> 0 | N24: L
A25: 20 | B25: Bruno Antunes | C25: Antunes | D25: 1 | E25: 0 | F25: 1 | G25: =E25/D25 -> 0 | H25: =+_xlfn.XLOOKUP(D25,$B$36:$B$54,$C$36:$C$54) -> 0.052631579 | I25: =+E25/D25 -> 0 | J25: =I25*H25 -> 0 | O25: L
A26: 20 | B26: Miguel Pacheco | C26: Mike | D26: 1 | E26: 0 | F26: 1 | G26: =E26/D26 -> 0 | H26: =+_xlfn.XLOOKUP(D26,$B$36:$B$54,$C$36:$C$54) -> 0.052631579 | I26: =+E26/D26 -> 0 | J26: =I26*H26 -> 0 | O26: L
A27: 20 | B27: Filipe Sá | C27: Sá | D27: 1 | E27: 0 | F27: 1 | G27: =E27/D27 -> 0 | H27: =+_xlfn.XLOOKUP(D27,$B$36:$B$54,$C$36:$C$54) -> 0.052631579 | I27: =+E27/D27 -> 0 | J27: =I27*H27 -> 0 | Q27: L
A28: 20 | B28: Renato Pereira | C28: Renato | D28: 1 | E28: 0 | F28: 1 | G28: =E28/D28 -> 0 | H28: =+_xlfn.XLOOKUP(D28,$B$36:$B$54,$C$36:$C$54) -> 0.052631579 | I28: =+E28/D28 -> 0 | J28: =I28*H28 -> 0 | R28: L
A29: 20 | B29: Rúben Costa | C29: Rúben | D29: 1 | E29: 0 | F29: 1 | G29: =E29/D29 -> 0 | H29: =+_xlfn.XLOOKUP(D29,$B$36:$B$54,$C$36:$C$54) -> 0.052631579 | I29: =+E29/D29 -> 0 | J29: =I29*H29 -> 0 | Z29: L
A30: 20 | B30: João Ramos | C30: Cona Torta | D30: 1 | E30: 0 | F30: 1 | G30: =E30/D30 -> 0 | H30: =+_xlfn.XLOOKUP(D30,$B$36:$B$54,$C$36:$C$54) -> 0.052631579 | I30: =+E30/D30 -> 0 | J30: =I30*H30 -> 0 | Z30: L
A31: 20 | B31: Alexandre Silva | C31: Peixe | D31: 1 | E31: 0 | F31: 1 | G31: =E31/D31 -> 0 | H31: =+_xlfn.XLOOKUP(D31,$B$36:$B$54,$C$36:$C$54) -> 0.052631579 | I31: =+E31/D31 -> 0 | J31: =I31*H31 -> 0 | Z31: L
D32: =SUM(D3:D31) -> 190 | E32: =SUM(E3:E31) -> 95 | F32: =SUM(F3:F31) -> 95
B33: Numero de semanas | D33: =D32/10 -> 19
B35: Fator | G35: {=TRANSPOSE(F36:F46)} -> Capela | H35: Quim | I35: Vieira | J35: Edu | K35: Campos | L35: Dimas | M35: Zé Miguel | N35: Tigas | O35: Xico Sant. | P35: Gui M. | Q35: João S. | S35: 45369 | T35: Capela vs Xico Santos | X35: Maior streak de vitórias | AA35: Xico S. | AB35: 5
B36: 1 | C36: =+B36/$D$33 -> 0.052631579 | F36: Capela | H36: =G37 -> 45418 | I36: =G38 -> 45376 | J36: 45467 | O36: =G44 -> 18/mar e 13/mai | P36: 45397 | Q36: =G46 -> 45502 | S36: 45376 | T36: Capela vs Vieira | X36: Streak de vitórias atual | AA36: Zé Miguel | AB36: 4
B37: 2 | C37: =+B37/$D$33 -> 0.10526316 | F37: Quim | G37: 45418 | J37: =H39 -> 45411 | K37: 45460 | N37: 45488 | S37: 45383 | T37: Sugestão Capela | X37: Maior streak de derrotas | AA37: Tigas | AB37: 8
B38: 3 | C38: =+B38/$D$33 -> 0.15789474 | F38: Vieira | G38: 45376 | K38: 45476 | M38: 45446 | O38: 45390 | S38: 45390 | T38: Xico S. vs Vieira | X38: Streak de derrotas atual | AA38: Órfão | AB38: 3
B39: 4 | C39: =+B39/$D$33 -> 0.21052632 | F39: Edu | G39: 45467 | H39: 45411 | L39: 45453 | S39: 45397 | T39: Capela vs Gui
B40: 5 | C40: =+B40/$D$33 -> 0.26315789 | F40: Campos | H40: 45460 | I40: 45476 | N40: 45432 | S40: 45404 | T40: Sugestão Gui | X40: Presenças
B41: 6 | C41: =+B41/$D$33 -> 0.31578947 | F41: Dimas | J41: 45453 | M41: 45481 | O41: 45495 | S41: 45411 | T41: Edu vs Quim | X41: Top10 | Y41: Nome | Z41: Jogos | AA41: Restantes | AB41: Nome | AC41: Jogos
...

Sheet UCL WS
A1: Retorta League WS (05/09/2024 a 28/01/2025)
A2: Ranking | B2: Jogadores | C2: Alcunha | D2: Jogos | E2: Vitórias | F2: Derrotas | G2: Win Rate | H2: Fator | I2: Média base | J2: Média ponderada | L2: 45540 | M2: 45551 | N2: 45558 | O2: 45565 | P2: 45572 | Q2: 45579 | R2: 45586 | S2: 45593 | T2: 45600 | U2: 45607 | V2: 45615 | W2: 45621 | X2: 45629 | Y2: 45635 | Z2: 45643 | AA2: 45663 | AB2: 45670 | AC2: 45677 | AD2: 45685
A3: 1 | B3: João Capela | C3: Capela | D3: 18 | E3: 13 | F3: 5 | G3: =E3/D3 -> 0.72222222 | H3: =VLOOKUP(D3,$B$40:$C$57,2,FALSE) -> 0.94736842 | I3: =+E3/D3 -> 0.72222222 | J3: =I3*H3 -> 0.68421053 | L3: L | M3: W | N3: W | O3: W | Q3: L | R3: L | S3: W | T3: W | U3: W | V3: W | W3: W | X3: L | Y3: W | Z3: W | AA3: W | AB3: W | AC3: L | AD3: W
A4: 2 | B4: Rodrigo Silva | C4: Rodrigo | D4: 16 | E4: 9 | F4: 7 | G4: =E4/D4 -> 0.5625 | H4: =VLOOKUP(D4,$B$40:$C$57,2,FALSE) -> 0.84210526 | I4: =+E4/D4 -> 0.5625 | J4: =I4*H4 -> 0.47368421 | M4: L | N4: W | O4: W | P4: L | Q4: W | R4: W | S4: L | T4: W | U4: W | V4: W | W4: L | X4: L | Y4: L | AB4: W | AC4: W | AD4: L
A5: 3 | B5: Joaquim Torrão | C5: Quim | D5: 15 | E5: 8 | F5: 7 | G5: =E5/D5 -> 0.53333333 | H5: =VLOOKUP(D5,$B$40:$C$57,2,FALSE) -> 0.78947368 | I5: =+E5/D5 -> 0.53333333 | J5: =I5*H5 -> 0.42105263 | P5: W | Q5: L | R5: L | S5: W | T5: L | U5: W | V5: W | W5: L | X5: W | Y5: W | Z5: L | AA5: W | AB5: W | AC5: L | AD5: L
A6: 3 | B6: Francisco Campos | C6: Campos | D6: 15 | E6: 8 | F6: 7 | G6: =E6/D6 -> 0.53333333 | H6: =VLOOKUP(D6,$B$40:$C$57,2,FALSE) -> 0.78947368 | I6: =+E6/D6 -> 0.53333333 | J6: =I6*H6 -> 0.42105263 | L6: L | M6: L | O6: W | P6: W | Q6: W | T6: L | U6: W | W6: L | X6: L | Y6: W | Z6: L | AA6: W | AB6: W | AC6: W | AD6: L
A7: 5 | B7: Francisco Santos | C7: Xico Santos | D7: 11 | E7: 7 | F7: 4 | G7: =E7/D7 -> 0.63636364 | H7: =VLOOKUP(D7,$B$40:$C$57,2,FALSE) -> 0.57894737 | I7: =+E7/D7 -> 0.63636364 | J7: =I7*H7 -> 0.36842105 | L7: W | M7: W | N7: L | O7: W | P7: L | S7: W | X7: W | Y7: W | Z7: L | AB7: L | AD7: W
A8: 5 | B8: Simão Mendes | C8: Simão | D8: 13 | E8: 7 | F8: 6 | G8: =E8/D8 -> 0.53846154 | H8: =VLOOKUP(D8,$B$40:$C$57,2,FALSE) -> 0.68421053 | I8: =+E8/D8 -> 0.53846154 | J8: =I8*H8 -> 0.36842105 | N8: W | O8: L | P8: W | R8: W | S8: L | T8: L | V8: L | W8: W | X8: W | Y8: L | AB8: L | AC8: W | AD8: W
A9: 7 | B9: João Silva | C9: Alex | D9: 15 | E9: 6 | F9: 9 | G9: =E9/D9 -> 0.4 | H9: =VLOOKUP(D9,$B$40:$C$57,2,FALSE) -> 0.78947368 | I9: =+E9/D9 -> 0.4 | J9: =I9*H9 -> 0.31578947 | M9: L | N9: L | O9: W | P9: L | R9: W | S9: L | T9: W | U9: L | V9: W | W9: W | X9: L | Y9: L | AB9: L | AC9: W | AD9: L
A10: 7 | B10: Pedro Vieira | C10: Vieira | D10: 12 | E10: 6 | F10: 6 | G10: =E10/D10 -> 0.5 | H10: =VLOOKUP(D10,$B$40:$C$57,2,FALSE) -> 0.63157895 | I10: =+E10/D10 -> 0.5 | J10: =I10*H10 -> 0.31578947 | L10: W | M10: L | O10: L | P10: L | Q10: W | R10: L | S10: W | T10: W | U10: L | V10: L | X10: W | Z10: W
A11: 9 | B11: Renato Pereira | C11: Renato | D11: 9 | E11: 4 | F11: 5 | G11: =E11/D11 -> 0.44444444 | H11: =VLOOKUP(D11,$B$40:$C$57,2,FALSE) -> 0.47368421 | I11: =+E11/D11 -> 0.44444444 | J11: =I11*H11 -> 0.21052632 | Q11: L | R11: W | T11: W | W11: L | Y11: W | Z11: L | AA11: L | AC11: L | AD11: W
A12: 10 | B12: Guilherme Moura | C12: Gui Moura | D12: 8 | E12: 3 | F12: 5 | G12: =E12/D12 -> 0.375 | H12: =VLOOKUP(D12,$B$40:$C$57,2,FALSE) -> 0.42105263 | I12: =+E12/D12 -> 0.375 | J12: =I12*H12 -> 0.15789474 | Q12: L | R12: L | T12: L | X12: W | Z12: W | AA12: L | AB12: W | AC12: L
A13: 10 | B13: Rui Vaz | C13: Rui Vaz | D13: 8 | E13: 3 | F13: 5 | G13: =E13/D13 -> 0.375 | H13: =VLOOKUP(D13,$B$40:$C$57,2,FALSE) -> 0.42105263 | I13: =+E13/D13 -> 0.375 | J13: =I13*H13 -> 0.15789474 | M13: W | O13: L | P13: W | S13: L | U13: L | W13: L | Z13: L | AA13: W
A14: 10 | B14: João Santos | C14: Jorginho | D14: 7 | E14: 3 | F14: 4 | G14: =E14/D14 -> 0.42857143 | H14: =VLOOKUP(D14,$B$40:$C$57,2,FALSE) -> 0.36842105 | I14: =+E14/D14 -> 0.42857143 | J14: =I14*H14 -> 0.15789474 | L14: L | O14: L | Q14: W | S14: L | T14: L | U14: W | W14: W
A15: 13 | B15: Francisco Sá | C15: Xico Sá | D15: 5 | E15: 2 | F15: 3 | G15: =E15/D15 -> 0.4 | H15: =VLOOKUP(D15,$B$40:$C$57,2,FALSE) -> 0.26315789 | I15: =+E15/D15 -> 0.4 | J15: =I15*H15 -> 0.10526316 | R15: W | U15: L | V15: L | X15: L | Z15: W
A16: 13 | B16: Francisco Fonte | C16: Fonte | D16: 5 | E16: 2 | F16: 3 | G16: =E16/D16 -> 0.4 | H16: =VLOOKUP(D16,$B$40:$C$57,2,FALSE) -> 0.26315789 | I16: =+E16/D16 -> 0.4 | J16: =I16*H16 -> 0.10526316 | U16: L | W16: W | AB16: L | AC16: W | AD16: L
A17: 13 | B17: Rui Dimas | C17: Dimas | D17: 4 | E17: 2 | F17: 2 | G17: =E17/D17 -> 0.5 | H17: =VLOOKUP(D17,$B$40:$C$57,2,FALSE) -> 0.21052632 | I17: =+E17/D17 -> 0.5 | J17: =I17*H17 -> 0.10526316 | M17: L | P17: W | Q17: W | R17: L
A18: 13 | B18: Diogo Duarte | C18: Insua | D18: 3 | E18: 2 | F18: 1 | G18: =E18/D18 -> 0.66666667 | H18: =VLOOKUP(D18,$B$40:$C$57,2,FALSE) -> 0.15789474 | I18: =+E18/D18 -> 0.66666667 | J18: =I18*H18 -> 0.10526316 | L18: L | M18: W | N18: W
A19: 13 | B19: Filipe Gomes | C19: Mini | D19: 3 | E19: 2 | F19: 1 | G19: =E19/D19 -> 0.66666667 | H19: =VLOOKUP(D19,$B$40:$C$57,2,FALSE) -> 0.15789474 | I19: =+E19/D19 -> 0.66666667 | J19: =I19*H19 -> 0.10526316 | L19: W | N19: L | Z19: W
A20: 18 | B20: Rosa | C20: Rosa | D20: 3 | E20: 1 | F20: 2 | G20: =E20/D20 -> 0.33333333 | H20: =VLOOKUP(D20,$B$40:$C$57,2,FALSE) -> 0.15789474 | I20: =+E20/D20 -> 0.33333333 | J20: =I20*H20 -> 0.052631579 | AA20: L | AC20: L | AD20: W
A21: 18 | B21: Daniel Marafona | C21: Mara | D21: 2 | E21: 1 | F21: 1 | G21: =E21/D21 -> 0.5 | H21: =VLOOKUP(D21,$B$40:$C$57,2,FALSE) -> 0.10526316 | I21: =+E21/D21 -> 0.5 | J21: =I21*H21 -> 0.052631579 | S21: W | Y21: L
A22: 18 | B22: José Miguel Ferreira | C22: Zé Miguel | D22: 2 | E22: 1 | F22: 1 | G22: =E22/D22 -> 0.5 | H22: =VLOOKUP(D22,$B$40:$C$57,2,FALSE) -> 0.10526316 | I22: =+E22/D22 -> 0.5 | J22: =I22*H22 -> 0.052631579 | V22: L | AA22: W
A23: 18 | B23: Ricardo Miranda | C23: Miranda Sr. | D23: 1 | E23: 1 | F23: 0 | G23: =E23/D23 -> 1 | H23: =VLOOKUP(D23,$B$40:$C$57,2,FALSE) -> 0.052631579 | I23: =+E23/D23 -> 1 | J23: =I23*H23 -> 0.052631579 | L23: W
A24: 18 | C24: Slim | D24: 1 | E24: 1 | F24: 0 | G24: =E24/D24 -> 1 | H24: =VLOOKUP(D24,$B$40:$C$57,2,FALSE) -> 0.052631579 | I24: =+E24/D24 -> 1 | J24: =I24*H24 -> 0.052631579 | L24: W
A25: 18 | B25: Bruno Silva | C25: Bruno | D25: 1 | E25: 1 | F25: 0 | G25: =E25/D25 -> 1 | H25: =VLOOKUP(D25,$B$40:$C$57,2,FALSE) -> 0.052631579 | I25: =+E25/D25 -> 1 | J25: =I25*H25 -> 0.052631579 | M25: W
A26: 18 | B26: João Cruz | C26: Cruz | D26: 1 | E26: 1 | F26: 0 | G26: =E26/D26 -> 1 | H26: =VLOOKUP(D26,$B$40:$C$57,2,FALSE) -> 0.052631579 | I26: =+E26/D26 -> 1 | J26: =I26*H26 -> 0.052631579 | N26: W
A27: 18 | B27: André Ferreira | C27: Ferreira | D27: 1 | E27: 1 | F27: 0 | G27: =E27/D27 -> 1 | H27: =VLOOKUP(D27,$B$40:$C$57,2,FALSE) -> 0.052631579 | I27: =+E27/D27 -> 1 | J27: =I27*H27 -> 0.052631579 | V27: W
A28: 26 | B28: Fernando | C28: Nando | D28: 3 | E28: 0 | F28: 3 | G28: =E28/D28 -> 0 | H28: =VLOOKUP(D28,$B$40:$C$57,2,FALSE) -> 0.15789474 | I28: =+E28/D28 -> 0 | J28: =I28*H28 -> 0 | O28: L | P28: L | Q28: L
A29: 26 | B29: José Costa | C29: Paralelo | D29: 2 | E29: 0 | F29: 2 | G29: =E29/D29 -> 0 | H29: =VLOOKUP(D29,$B$40:$C$57,2,FALSE) -> 0.10526316 | I29: =+E29/D29 -> 0 | J29: =I29*H29 -> 0 | V29: L | AB29: L
A30: 26 | B30: Guilherme Macedo | C30: Macedo | D30: 1 | E30: 0 | F30: 1 | G30: =E30/D30 -> 0 | H30: =VLOOKUP(D30,$B$40:$C$57,2,FALSE) -> 0.052631579 | I30: =+E30/D30 -> 0 | J30: =I30*H30 -> 0 | L30: L
A31: 26 | B31: Raul Trocado | C31: Trocado | D31: 1 | E31: 0 | F31: 1 | G31: =E31/D31 -> 0 | H31: =VLOOKUP(D31,$B$40:$C$57,2,FALSE) -> 0.052631579 | I31: =+E31/D31 -> 0 | J31: =I31*H31 -> 0 | N31: L
A32: 26 | B32: Tiago Lima | C32: Lima | D32: 1 | E32: 0 | F32: 1 | G32: =E32/D32 -> 0 | H32: =VLOOKUP(D32,$B$40:$C$57,2,FALSE) -> 0.052631579 | I32: =+E32/D32 -> 0 | J32: =I32*H32 -> 0 | N32: L
A33: 26 | B33: Diogo Souto | C33: Souto | D33: 1 | E33: 0 | F33: 1 | G33: =E33/D33 -> 0 | H33: =VLOOKUP(D33,$B$40:$C$57,2,FALSE) -> 0.052631579 | I33: =+E33/D33 -> 0 | J33: =I33*H33 -> 0 | Y33: L
A34: 26 | B34: Francisco Silva | C34: Xico Silva | D34: 1 | E34: 0 | F34: 1 | G34: =E34/D34 -> 0 | H34: =VLOOKUP(D34,$B$40:$C$57,2,FALSE) -> 0.052631579 | I34: =+E34/D34 -> 0 | J34: =I34*H34 -> 0 | AA34: L
A35: 26 | B35: Bruno Maia | C35: Maia | D35: 1 | E35: 0 | F35: 1 | G35: =E35/D35 -> 0 | H35: =VLOOKUP(D35,$B$40:$C$57,2,FALSE) -> 0.052631579 | I35: =+E35/D35 -> 0 | J35: =I35*H35 -> 0 | AA35: L
D36: =SUM(D3:D35) -> 190 | E36: =SUM(E3:E35) -> 95 | F36: =SUM(F3:F35) -> 95
B37: Numero de semanas | D37: =D36/10 -> 19
B39: Fator | G39: {=TRANSPOSE(F40:F50)} -> Capela | H39: Quim | I39: Vieira | J39: Jorginho | K39: Campos | L39: Dimas | M39: Alex | N39: Rodri | O39: Xico Sant. | P39: Rui Vaz | Q39: Simão | S39: 45540 | T39: Vieira vs Capela | X39: Maior streak de vitórias | AA39: Capela | AC39: 5
B40: 1 | C40: =B40/$D$37 -> 0.052631579 | F40: Capela | H40: 45621 | I40: 45540 | N40: 21/out e 28/jan | S40: 45544 | T40: A. Vieira vs A. Capela | X40: Streak de vitórias atual | AA40: Simão, Vieira, Jorginho e Insua | AC40: 2
B41: 2 | C41: =B41/$D$37 -> 0.10526316 | F41: Quim | G41: 45621 | L41: 45579 | M41: 45670 | S41: 45551 | T41: Vieira vs Xico Santos | X41: Maior streak de derrotas | AA41: Rui Vaz | AC41: 4
...

Sheet UCL SS 2ed
A1: Retorta League SS 2ed (06/03/2025 a 07/07/2025)
A2: Ranking | B2: Jogadores | C2: Alcunha | D2: Jogos | E2: Vitórias | F2: Derrotas | G2: Win Rate | H2: Fator | I2: Média base | J2: Média ponderada | L2: 45722 | M2: 45729 | N2: 45733 | O2: 45740 | P2: 45747 | Q2: 45754 | R2: 45761 | S2: 45768 | T2: 45776 | U2: 45782 | V2: 45789 | W2: 45796 | X2: 45803 | Y2: 45813 | Z2: 45819 | AA2: 45824 | AB2: 45834 | AC2: 45838 | AD2: =AC2+7 -> 45845
A3: 1 | B3: Joaquim Torrão | C3: Quim | D3: =+COUNTA(L3:AD3) -> 19 | E3: =+COUNTIF(L3:AD3,"W") -> 12 | F3: =+COUNTIF(L3:AD3,"L") -> 7 | G3: =E3/D3 -> 0.63157895 | H3: =VLOOKUP(D3,$B$55:$C$73,2,FALSE) -> 1 | I3: =+E3/D3 -> 0.63157895 | J3: =I3*H3 -> 0.63157895 | L3: W | M3: W | N3: W | O3: L | P3: L | Q3: W | R3: L | S3: L | T3: W | U3: L | V3: W | W3: W | X3: W | Y3: W | Z3: L | AA3: W | AB3: L | AC3: W | AD3: W
A4: 2 | B4: João Capela | C4: Capela | D4: =+COUNTA(L4:AD4) -> 18 | E4: =+COUNTIF(L4:AD4,"W") -> 9 | F4: =+COUNTIF(L4:AD4,"L") -> 9 | G4: =E4/D4 -> 0.5 | H4: =VLOOKUP(D4,$B$55:$C$73,2,FALSE) -> 0.94736842 | I4: =+E4/D4 -> 0.5 | J4: =I4*H4 -> 0.47368421 | L4: W | M4: L | N4: L | O4: W | P4: W | R4: L | S4: L | T4: W | U4: L | V4: W | W4: W | X4: W | Y4: L | Z4: W | AA4: L | AB4: W | AC4: L | AD4: L
A5: 3 | B5: Renato Pereira | C5: Renato | D5: =+COUNTA(L5:AD5) -> 12 | E5: =+COUNTIF(L5:AD5,"W") -> 7 | F5: =+COUNTIF(L5:AD5,"L") -> 5 | G5: =E5/D5 -> 0.58333333 | H5: =VLOOKUP(D5,$B$55:$C$73,2,FALSE) -> 0.63157895 | I5: =+E5/D5 -> 0.58333333 | J5: =I5*H5 -> 0.36842105 | L5: L | M5: W | N5: W | O5: L | P5: W | Q5: L | R5: W | S5: W | T5: L | U5: W | W5: W | X5: L
A6: 4 | B6: Pedro Vieira | C6: Vieira | D6: =+COUNTA(L6:AD6) -> 12 | E6: =+COUNTIF(L6:AD6,"W") -> 6 | F6: =+COUNTIF(L6:AD6,"L") -> 6 | G6: =E6/D6 -> 0.5 | H6: =VLOOKUP(D6,$B$55:$C$73,2,FALSE) -> 0.63157895 | I6: =+E6/D6 -> 0.5 | J6: =I6*H6 -> 0.31578947 | M6: L | N6: L | P6: W | Q6: L | R6: L | S6: W | V6: L | W6: L | X6: W | AB6: W | AC6: W | AD6: W
A7: 5 | B7: Simão Mendes | C7: Simão | D7: =+COUNTA(L7:AD7) -> 7 | E7: =+COUNTIF(L7:AD7,"W") -> 5 | F7: =+COUNTIF(L7:AD7,"L") -> 2 | G7: =E7/D7 -> 0.71428571 | H7: =VLOOKUP(D7,$B$55:$C$73,2,FALSE) -> 0.36842105 | I7: =+E7/D7 -> 0.71428571 | J7: =I7*H7 -> 0.26315789 | N7: W | P7: L | Q7: W | S7: W | U7: W | V7: L | W7: W
A8: 5 | B8: Francisco Campos | C8: Campos | D8: =+COUNTA(L8:AD8) -> 9 | E8: =+COUNTIF(L8:AD8,"W") -> 5 | F8: =+COUNTIF(L8:AD8,"L") -> 4 | G8: =E8/D8 -> 0.55555556 | H8: =VLOOKUP(D8,$B$55:$C$73,2,FALSE) -> 0.47368421 | I8: =+E8/D8 -> 0.55555556 | J8: =I8*H8 -> 0.26315789 | O8: W | Q8: W | R8: W | S8: L | X8: L | Y8: W | AB8: W | AC8: L | AD8: L
A9: 5 | B9: Dinis Pontes | C9: Trator | D9: =+COUNTA(L9:AD9) -> 9 | E9: =+COUNTIF(L9:AD9,"W") -> 5 | F9: =+COUNTIF(L9:AD9,"L") -> 4 | G9: =E9/D9 -> 0.55555556 | H9: =VLOOKUP(D9,$B$55:$C$73,2,FALSE) -> 0.47368421 | I9: =+E9/D9 -> 0.55555556 | J9: =I9*H9 -> 0.26315789 | V9: L | W9: L | X9: W | Y9: W | Z9: L | AA9: W | AB9: L | AC9: W | AD9: W
A10: 8 | B10: Diogo Souto | C10: Souto | D10: =+COUNTA(L10:AD10) -> 6 | E10: =+COUNTIF(L10:AD10,"W") -> 4 | F10: =+COUNTIF(L10:AD10,"L") -> 2 | G10: =E10/D10 -> 0.66666667 | H10: =VLOOKUP(D10,$B$55:$C$73,2,FALSE) -> 0.31578947 | I10: =+E10/D10 -> 0.66666667 | J10: =I10*H10 -> 0.21052632 | T10: W | U10: W | V10: W | W10: W | X10: L | AC10: L
A11: 8 | B11: João Silva | C11: Alex | D11: =+COUNTA(L11:AD11) -> 9 | E11: =+COUNTIF(L11:AD11,"W") -> 4 | F11: =+COUNTIF(L11:AD11,"L") -> 5 | G11: =E11/D11 -> 0.44444444 | H11: =VLOOKUP(D11,$B$55:$C$73,2,FALSE) -> 0.47368421 | I11: =+E11/D11 -> 0.44444444 | J11: =I11*H11 -> 0.21052632 | N11: W | O11: L | Q11: L | S11: W | U11: L | V11: W | X11: L | Z11: L | AC11: W
A12: 10 | B12: Francisco Fonte | C12: Fonte | D12: =+COUNTA(L12:AD12) -> 4 | E12: =+COUNTIF(L12:AD12,"W") -> 3 | F12: =+COUNTIF(L12:AD12,"L") -> 1 | G12: =E12/D12 -> 0.75 | H12: =VLOOKUP(D12,$B$55:$C$73,2,FALSE) -> 0.21052632 | I12: =+E12/D12 -> 0.75 | J12: =I12*H12 -> 0.15789474 | N12: W | O12: W | Q12: L | S12: W
A13: 10 | B13: Rosa | C13: Rosa | D13: =+COUNTA(L13:AD13) -> 6 | E13: =+COUNTIF(L13:AD13,"W") -> 3 | F13: =+COUNTIF(L13:AD13,"L") -> 3 | G13: =E13/D13 -> 0.5 | H13: =VLOOKUP(D13,$B$55:$C$73,2,FALSE) -> 0.31578947 | I13: =+E13/D13 -> 0.5 | J13: =I13*H13 -> 0.15789474 | L13: L | M13: L | Q13: W | R13: W | T13: L | U13: W
A14: 10 | B14: Raul Trocado | C14: Trocado | D14: =+COUNTA(L14:AD14) -> 3 | E14: =+COUNTIF(L14:AD14,"W") -> 3 | F14: =+COUNTIF(L14:AD14,"L") -> 0 | G14: =E14/D14 -> 1 | H14: =VLOOKUP(D14,$B$55:$C$73,2,FALSE) -> 0.15789474 | I14: =+E14/D14 -> 1 | J14: =I14*H14 -> 0.15789474 | L14: W | P14: W | AB14: W
A15: 13 | B15: Guilherme Moura | C15: Gui Moura | D15: =+COUNTA(L15:AD15) -> 11 | E15: =+COUNTIF(L15:AD15,"W") -> 2 | F15: =+COUNTIF(L15:AD15,"L") -> 9 | G15: =E15/D15 -> 0.18181818 | H15: =VLOOKUP(D15,$B$55:$C$73,2,FALSE) -> 0.57894737 | I15: =+E15/D15 -> 0.18181818 | J15: =I15*H15 -> 0.10526316 | L15: L | M15: L | N15: L | O15: L | P15: W | Q15: L | R15: W | S15: L | T15: L | X15: L | AC15: L
A16: 13 | B16: Diogo Duarte | C16: Insua | D16: =+COUNTA(L16:AD16) -> 7 | E16: =+COUNTIF(L16:AD16,"W") -> 2 | F16: =+COUNTIF(L16:AD16,"L") -> 5 | G16: =E16/D16 -> 0.28571429 | H16: =VLOOKUP(D16,$B$55:$C$73,2,FALSE) -> 0.36842105 | I16: =+E16/D16 -> 0.28571429 | J16: =I16*H16 -> 0.10526316 | T16: L | U16: L | V16: W | W16: L | X16: W | Y16: L | Z16: L
A17: 13 | B17: Rodrigo Silva | C17: Rodrigo | D17: =+COUNTA(L17:AD17) -> 4 | E17: =+COUNTIF(L17:AD17,"W") -> 2 | F17: =+COUNTIF(L17:AD17,"L") -> 2 | G17: =E17/D17 -> 0.5 | H17: =VLOOKUP(D17,$B$55:$C$73,2,FALSE) -> 0.21052632 | I17: =+E17/D17 -> 0.5 | J17: =I17*H17 -> 0.10526316 | O17: L | Q17: W | S17: L | Z17: W
A18: 13 | B18: Pedro Gomes | C18: Jonas | D18: =+COUNTA(L18:AD18) -> 3 | E18: =+COUNTIF(L18:AD18,"W") -> 2 | F18: =+COUNTIF(L18:AD18,"L") -> 1 | G18: =E18/D18 -> 0.66666667 | H18: =VLOOKUP(D18,$B$55:$C$73,2,FALSE) -> 0.15789474 | I18: =+E18/D18 -> 0.66666667 | J18: =I18*H18 -> 0.10526316 | R18: L | Y18: W | Z18: W
A19: 13 | B19: João Órfão | C19: Órfão | D19: =+COUNTA(L19:AD19) -> 4 | E19: =+COUNTIF(L19:AD19,"W") -> 2 | F19: =+COUNTIF(L19:AD19,"L") -> 2 | G19: =E19/D19 -> 0.5 | H19: =VLOOKUP(D19,$B$55:$C$73,2,FALSE) -> 0.21052632 | I19: =+E19/D19 -> 0.5 | J19: =I19*H19 -> 0.10526316 | Y19: L | Z19: W | AA19: W | AD19: L
A20: 13 | B20: Gonçalo Fernandes | C20: Gonças | D20: =+COUNTA(L20:AD20) -> 2 | E20: =+COUNTIF(L20:AD20,"W") -> 2 | F20: =+COUNTIF(L20:AD20,"L") -> 0 | G20: =E20/D20 -> 1 | H20: =VLOOKUP(D20,$B$55:$C$73,2,FALSE) -> 0.10526316 | I20: =+E20/D20 -> 1 | J20: =I20*H20 -> 0.10526316 | AA20: W | AB20: W
A21: 19 | B21: José Miguel Ferreira | C21: Zé Miguel | D21: =+COUNTA(L21:AD21) -> 3 | E21: =+COUNTIF(L21:AD21,"W") -> 1 | F21: =+COUNTIF(L21:AD21,"L") -> 2 | G21: =E21/D21 -> 0.33333333 | H21: =VLOOKUP(D21,$B$55:$C$73,2,FALSE) -> 0.15789474 | I21: =+E21/D21 -> 0.33333333 | J21: =I21*H21 -> 0.052631579 | L21: L | O21: W | AB21: L
A22: 19 | B22: João Santos | C22: Jorginho | D22: =+COUNTA(L22:AD22) -> 3 | E22: =+COUNTIF(L22:AD22,"W") -> 1 | F22: =+COUNTIF(L22:AD22,"L") -> 2 | G22: =E22/D22 -> 0.33333333 | H22: =VLOOKUP(D22,$B$55:$C$73,2,FALSE) -> 0.15789474 | I22: =+E22/D22 -> 0.33333333 | J22: =I22*H22 -> 0.052631579 | M22: W | Y22: L | AD22: L
A23: 19 | B23: Eduardo Maia | C23: Edu | D23: =+COUNTA(L23:AD23) -> 4 | E23: =+COUNTIF(L23:AD23,"W") -> 1 | F23: =+COUNTIF(L23:AD23,"L") -> 3 | G23: =E23/D23 -> 0.25 | H23: =VLOOKUP(D23,$B$55:$C$73,2,FALSE) -> 0.21052632 | I23: =+E23/D23 -> 0.25 | J23: =I23*H23 -> 0.052631579 | V23: L | AA23: L | AC23: W | AD23: L
A24: 19 | B24: António Amorim | C24: Toni | D24: =+COUNTA(L24:AD24) -> 1 | E24: =+COUNTIF(L24:AD24,"W") -> 1 | F24: =+COUNTIF(L24:AD24,"L") -> 0 | G24: =E24/D24 -> 1 | H24: =VLOOKUP(D24,$B$55:$C$73,2,FALSE) -> 0.052631579 | I24: =+E24/D24 -> 1 | J24: =I24*H24 -> 0.052631579 | L24: W
A25: 19 | B25: Tiago Lima | C25: Lima | D25: =+COUNTA(L25:AD25) -> 2 | E25: =+COUNTIF(L25:AD25,"W") -> 1 | F25: =+COUNTIF(L25:AD25,"L") -> 1 | G25: =E25/D25 -> 0.5 | H25: =VLOOKUP(D25,$B$55:$C$73,2,FALSE) -> 0.10526316 | I25: =+E25/D25 -> 0.5 | J25: =I25*H25 -> 0.052631579 | L25: W | P25: L
A26: 19 | B26: Rui Dimas | C26: Dimas | D26: =+COUNTA(L26:AD26) -> 2 | E26: =+COUNTIF(L26:AD26,"W") -> 1 | F26: =+COUNTIF(L26:AD26,"L") -> 1 | G26: =E26/D26 -> 0.5 | H26: =VLOOKUP(D26,$B$55:$C$73,2,FALSE) -> 0.10526316 | I26: =+E26/D26 -> 0.5 | J26: =I26*H26 -> 0.052631579 | M26: W | Z26: L
A27: 19 | B27: Tiago Filipe | C27: Tigas | D27: =+COUNTA(L27:AD27) -> 1 | E27: =+COUNTIF(L27:AD27,"W") -> 1 | F27: =+COUNTIF(L27:AD27,"L") -> 0 | G27: =E27/D27 -> 1 | H27: =VLOOKUP(D27,$B$55:$C$73,2,FALSE) -> 0.052631579 | I27: =+E27/D27 -> 1 | J27: =I27*H27 -> 0.052631579 | M27: W
A28: 19 | B28: Adriano Pereira | C28: Adri | D28: =+COUNTA(L28:AD28) -> 1 | E28: =+COUNTIF(L28:AD28,"W") -> 1 | F28: =+COUNTIF(L28:AD28,"L") -> 0 | G28: =E28/D28 -> 1 | H28: =VLOOKUP(D28,$B$55:$C$73,2,FALSE) -> 0.052631579 | I28: =+E28/D28 -> 1 | J28: =I28*H28 -> 0.052631579 | O28: W
A29: 19 | B29: Luís Guimarães | C29: Guimarães | D29: =+COUNTA(L29:AD29) -> 1 | E29: =+COUNTIF(L29:AD29,"W") -> 1 | F29: =+COUNTIF(L29:AD29,"L") -> 0 | G29: =E29/D29 -> 1 | H29: =VLOOKUP(D29,$B$55:$C$73,2,FALSE) -> 0.052631579 | I29: =+E29/D29 -> 1 | J29: =I29*H29 -> 0.052631579 | R29: W
A30: 19 | B30: Francisco Santos | C30: Xico Santos | D30: =+COUNTA(L30:AD30) -> 1 | E30: =+COUNTIF(L30:AD30,"W") -> 1 | F30: =+COUNTIF(L30:AD30,"L") -> 0 | G30: =E30/D30 -> 1 | H30: =VLOOKUP(D30,$B$55:$C$73,2,FALSE) -> 0.052631579 | I30: =+E30/D30 -> 1 | J30: =I30*H30 -> 0.052631579 | T30: W
A31: 19 | B31: Daniel Marafona | C31: Mara | D31: =+COUNTA(L31:AD31) -> 1 | E31: =+COUNTIF(L31:AD31,"W") -> 1 | F31: =+COUNTIF(L31:AD31,"L") -> 0 | G31: =E31/D31 -> 1 | H31: =VLOOKUP(D31,$B$55:$C$73,2,FALSE) -> 0.052631579 | I31: =+E31/D31 -> 1 | J31: =I31*H31 -> 0.052631579 | T31: W
A32: 19 | B32: Paulo Ferreira | C32: Paulo | D32: =+COUNTA(L32:AD32) -> 2 | E32: =+COUNTIF(L32:AD32,"W") -> 1 | F32: =+COUNTIF(L32:AD32,"L") -> 1 | G32: =E32/D32 -> 0.5 | H32: =VLOOKUP(D32,$B$55:$C$73,2,FALSE) -> 0.10526316 | I32: =+E32/D32 -> 0.5 | J32: =I32*H32 -> 0.052631579 | T32: L | U32: W
A33: 19 | B33: José Domingos | C33: Zé Domingos | D33: =+COUNTA(L33:AD33) -> 1 | E33: =+COUNTIF(L33:AD33,"W") -> 1 | F33: =+COUNTIF(L33:AD33,"L") -> 0 | G33: =E33/D33 -> 1 | H33: =VLOOKUP(D33,$B$55:$C$73,2,FALSE) -> 0.052631579 | I33: =+E33/D33 -> 1 | J33: =I33*H33 -> 0.052631579 | Y33: W
A34: 19 | B34: Leandro Terroso | C34: Zé Li | D34: =+COUNTA(L34:AD34) -> 2 | E34: =+COUNTIF(L34:AD34,"W") -> 1 | F34: =+COUNTIF(L34:AD34,"L") -> 1 | G34: =E34/D34 -> 0.5 | H34: =VLOOKUP(D34,$B$55:$C$73,2,FALSE) -> 0.10526316 | I34: =+E34/D34 -> 0.5 | J34: =I34*H34 -> 0.052631579 | Z34: W | AA34: L
A35: 19 | B35: João Ramos | C35: Cona Torta | D35: =+COUNTA(L35:AD35) -> 2 | E35: =+COUNTIF(L35:AD35,"W") -> 1 | F35: =+COUNTIF(L35:AD35,"L") -> 1 | G35: =E35/D35 -> 0.5 | H35: =VLOOKUP(D35,$B$55:$C$73,2,FALSE) -> 0.10526316 | I35: =+E35/D35 -> 0.5 | J35: =I35*H35 -> 0.052631579 | AA35: W | AB35: L
A36: 19 | B36: Xavier Oliveira | C36: Xavi | D36: =+COUNTA(L36:AD36) -> 1 | E36: =+COUNTIF(L36:AD36,"W") -> 1 | F36: =+COUNTIF(L36:AD36,"L") -> 0 | G36: =E36/D36 -> 1 | H36: =VLOOKUP(D36,$B$55:$C$73,2,FALSE) -> 0.052631579 | I36: =+E36/D36 -> 1 | J36: =I36*H36 -> 0.052631579 | AD36: W
A37: 19 | B37: Pedro Miranda | C37: Miranda | D37: =+COUNTA(L37:AD37) -> 2 | E37: =+COUNTIF(L37:AD37,"W") -> 1 | F37: =+COUNTIF(L37:AD37,"L") -> 1 | G37: =E37/D37 -> 0.5 | H37: =VLOOKUP(D37,$B$55:$C$73,2,FALSE) -> 0.10526316 | I37: =+E37/D37 -> 0.5 | J37: =I37*H37 -> 0.052631579 | AA37: L | AD37: W
A38: 36 | B38: Leonardo Domingos | C38: Leo | D38: =+COUNTA(L38:AD38) -> 1 | E38: =+COUNTIF(L38:AD38,"W") -> 0 | F38: =+COUNTIF(L38:AD38,"L") -> 1 | G38: =E38/D38 -> 0 | H38: =VLOOKUP(D38,$B$55:$C$73,2,FALSE) -> 0.052631579 | I38: =+E38/D38 -> 0 | J38: =I38*H38 -> 0 | L38: L
A39: 36 | B39: Diogo Castro | C39: Castro | D39: =+COUNTA(L39:AD39) -> 1 | E39: =+COUNTIF(L39:AD39,"W") -> 0 | F39: =+COUNTIF(L39:AD39,"L") -> 1 | G39: =E39/D39 -> 0 | H39: =VLOOKUP(D39,$B$55:$C$73,2,FALSE) -> 0.052631579 | I39: =+E39/D39 -> 0 | J39: =I39*H39 -> 0 | M39: L
A40: 36 | B40: Diogo Azevedo | C40: Dipi | D40: =+COUNTA(L40:AD40) -> 1 | E40: =+COUNTIF(L40:AD40,"W") -> 0 | F40: =+COUNTIF(L40:AD40,"L") -> 1 | G40: =E40/D40 -> 0 | H40: =VLOOKUP(D40,$B$55:$C$73,2,FALSE) -> 0.052631579 | I40: =+E40/D40 -> 0 | J40: =I40*H40 -> 0 | N40: L
...

Sheet UCL WS 2ed
A1: Retorta League SS 2ed (08/09/2025 a 19/01/2026)
A2: Ranking | B2: Jogadores | C2: Alcunha | D2: Jogos | E2: Vitórias | F2: Derrotas | G2: Win Rate | H2: Fator | I2: Média base | J2: Média ponderada | L2: 45908 | M2: =+L2+7 -> 45915 | N2: =+M2+7 -> 45922 | O2: =+N2+7 -> 45929 | P2: =+O2+7 -> 45936 | Q2: =+P2+7 -> 45943 | R2: 45951 | S2: =+R2+7 -> 45958 | T2: =+S2+7 -> 45965 | U2: =+T2+7 -> 45972 | V2: 45978 | W2: 45986 | X2: =+W2+7 -> 45993 | Y2: =+X2+7 -> 46000 | Z2: =+Y2+7 -> 46007 | AA2: =+Z2+14 -> 46021 | AB2: =+AA2+7 -> 46028 | AC2: =+AB2+7 -> 46035 | AD2: =+AC2+7 -> 46042
A3: 1 | B3: Joaquim Torrão | C3: Quim | D3: =+COUNTA(L3:AD3) -> 18 | E3: =+COUNTIF(L3:AD3,"W") -> 12 | F3: =+COUNTIF(L3:AD3,"L") -> 6 | G3: =E3/D3 -> 0.66666667 | H3: =VLOOKUP(D3,$B$42:$C$60,2,FALSE) -> 0.94736842 | I3: =+E3/D3 -> 0.66666667 | J3: =I3*H3 -> 0.63157895 | L3: L | N3: L | O3: W | P3: W | Q3: L | R3: W | S3: W | T3: W | U3: W | V3: L | W3: L | X3: W | Y3: W | Z3: W | AA3: W | AB3: W | AC3: L | AD3: W
A4: 2 | B4: João Capela | C4: Capela | D4: =+COUNTA(L4:AD4) -> 18 | E4: =+COUNTIF(L4:AD4,"W") -> 10 | F4: =+COUNTIF(L4:AD4,"L") -> 8 | G4: =E4/D4 -> 0.55555556 | H4: =VLOOKUP(D4,$B$42:$C$60,2,FALSE) -> 0.94736842 | I4: =+E4/D4 -> 0.55555556 | J4: =I4*H4 -> 0.52631579 | L4: W | M4: L | N4: W | O4: W | P4: W | Q4: L | R4: W | S4: L | T4: L | U4: W | V4: L | W4: W | Y4: W | Z4: L | AA4: L | AB4: L | AC4: W | AD4: W
A5: 3 | B5: Raul Trocado | C5: Trocado | D5: =+COUNTA(L5:AD5) -> 12 | E5: =+COUNTIF(L5:AD5,"W") -> 9 | F5: =+COUNTIF(L5:AD5,"L") -> 3 | G5: =E5/D5 -> 0.75 | H5: =VLOOKUP(D5,$B$42:$C$60,2,FALSE) -> 0.63157895 | I5: =+E5/D5 -> 0.75 | J5: =I5*H5 -> 0.47368421 | R5: L | S5: L | T5: W | U5: W | V5: W | X5: W | Y5: L | Z5: W | AA5: W | AB5: W | AC5: W | AD5: W
A6: 4 | B6: Francisco Campos | C6: Campos | D6: =+COUNTA(L6:AD6) -> 14 | E6: =+COUNTIF(L6:AD6,"W") -> 8 | F6: =+COUNTIF(L6:AD6,"L") -> 6 | G6: =E6/D6 -> 0.57142857 | H6: =VLOOKUP(D6,$B$42:$C$60,2,FALSE) -> 0.73684211 | I6: =+E6/D6 -> 0.57142857 | J6: =I6*H6 -> 0.42105263 | L6: L | M6: W | S6: L | T6: W | U6: W | V6: L | W6: W | X6: W | Y6: L | Z6: W | AA6: W | AB6: L | AC6: W | AD6: L
A7: 5 | B7: Guilherme Moura | C7: Gui Moura | D7: =+COUNTA(L7:AD7) -> 14 | E7: =+COUNTIF(L7:AD7,"W") -> 6 | F7: =+COUNTIF(L7:AD7,"L") -> 8 | G7: =E7/D7 -> 0.42857143 | H7: =VLOOKUP(D7,$B$42:$C$60,2,FALSE) -> 0.73684211 | I7: =+E7/D7 -> 0.42857143 | J7: =I7*H7 -> 0.31578947 | M7: W | O7: L | P7: W | Q7: W | R7: L | U7: L | V7: W | W7: W | Y7: W | Z7: L | AA7: L | AB7: L | AC7: L | AD7: L
A8: 6 | B8: Eduardo Maia | C8: Edu | D8: =+COUNTA(L8:AD8) -> 17 | E8: =+COUNTIF(L8:AD8,"W") -> 6 | F8: =+COUNTIF(L8:AD8,"L") -> 11 | G8: =E8/D8 -> 0.35294118 | H8: =VLOOKUP(D8,$B$42:$C$60,2,FALSE) -> 0.89473684 | I8: =+E8/D8 -> 0.35294118 | J8: =I8*H8 -> 0.31578947 | L8: W | M8: W | O8: L | P8: L | Q8: L | R8: W | S8: L | T8: L | U8: L | V8: L | W8: L | X8: L | Y8: W | Z8: L | AB8: W | AC8: W | AD8: L
A9: 7 | B9: Diogo Canito | C9: Canito | D9: =+COUNTA(L9:AD9) -> 5 | E9: =+COUNTIF(L9:AD9,"W") -> 5 | F9: =+COUNTIF(L9:AD9,"L") -> 0 | G9: =E9/D9 -> 1 | H9: =VLOOKUP(D9,$B$42:$C$60,2,FALSE) -> 0.26315789 | I9: =+E9/D9 -> 1 | J9: =I9*H9 -> 0.26315789 | N9: W | O9: W | P9: W | S9: W | X9: W
A10: 8 | B10: Renato Pereira | C10: Renato | D10: =+COUNTA(L10:AD10) -> 12 | E10: =+COUNTIF(L10:AD10,"W") -> 5 | F10: =+COUNTIF(L10:AD10,"L") -> 7 | G10: =E10/D10 -> 0.41666667 | H10: =VLOOKUP(D10,$B$42:$C$60,2,FALSE) -> 0.63157895 | I10: =+E10/D10 -> 0.41666667 | J10: =I10*H10 -> 0.26315789 | M10: W | R10: L | U10: L | V10: W | W10: W | X10: L | Y10: W | Z10: L | AA10: W | AB10: L | AC10: L | AD10: L
A11: 9 | B11: Leandro Terroso | C11: Zé Li | D11: =+COUNTA(L11:AD11) -> 5 | E11: =+COUNTIF(L11:AD11,"W") -> 4 | F11: =+COUNTIF(L11:AD11,"L") -> 1 | G11: =E11/D11 -> 0.8 | H11: =VLOOKUP(D11,$B$42:$C$60,2,FALSE) -> 0.26315789 | I11: =+E11/D11 -> 0.8 | J11: =I11*H11 -> 0.21052632 | O11: W | P11: W | S11: W | Z11: W | AA11: L
A12: 10 | B12: Pedro Vieira | C12: Vieira | D12: =+COUNTA(L12:AD12) -> 7 | E12: =+COUNTIF(L12:AD12,"W") -> 4 | F12: =+COUNTIF(L12:AD12,"L") -> 3 | G12: =E12/D12 -> 0.57142857 | H12: =VLOOKUP(D12,$B$42:$C$60,2,FALSE) -> 0.36842105 | I12: =+E12/D12 -> 0.57142857 | J12: =I12*H12 -> 0.21052632 | L12: W | P12: L | R12: L | W12: L | AB12: W | AC12: W | AD12: W
A13: 11 | B13: José Miguel Ferreira | C13: Zé Miguel | D13: =+COUNTA(L13:AD13) -> 11 | E13: =+COUNTIF(L13:AD13,"W") -> 4 | F13: =+COUNTIF(L13:AD13,"L") -> 7 | G13: =E13/D13 -> 0.36363636 | H13: =VLOOKUP(D13,$B$42:$C$60,2,FALSE) -> 0.57894737 | I13: =+E13/D13 -> 0.36363636 | J13: =I13*H13 -> 0.21052632 | M13: L | O13: W | P13: L | Q13: W | S13: L | U13: L | V13: W | W13: L | X13: L | Z13: W | AC13: L
A14: 12 | B14: Gonçalo Silva | C14: Anke | D14: =+COUNTA(L14:AD14) -> 4 | E14: =+COUNTIF(L14:AD14,"W") -> 3 | F14: =+COUNTIF(L14:AD14,"L") -> 1 | G14: =E14/D14 -> 0.75 | H14: =VLOOKUP(D14,$B$42:$C$60,2,FALSE) -> 0.21052632 | I14: =+E14/D14 -> 0.75 | J14: =I14*H14 -> 0.15789474 | S14: W | T14: W | X14: W | Y14: L
A15: 13 | B15: Rui Vaz | C15: Rui Vaz | D15: =+COUNTA(L15:AD15) -> 3 | E15: =+COUNTIF(L15:AD15,"W") -> 2 | F15: =+COUNTIF(L15:AD15,"L") -> 1 | G15: =E15/D15 -> 0.66666667 | H15: =VLOOKUP(D15,$B$42:$C$60,2,FALSE) -> 0.15789474 | I15: =+E15/D15 -> 0.66666667 | J15: =I15*H15 -> 0.10526316 | R15: L | S15: W | T15: W
A16: 14 | B16: João Alex Silva | C16: Alex | D16: =+COUNTA(L16:AD16) -> 4 | E16: =+COUNTIF(L16:AD16,"W") -> 2 | F16: =+COUNTIF(L16:AD16,"L") -> 2 | G16: =E16/D16 -> 0.5 | H16: =VLOOKUP(D16,$B$42:$C$60,2,FALSE) -> 0.21052632 | I16: =+E16/D16 -> 0.5 | J16: =I16*H16 -> 0.10526316 | M16: W | Q16: L | V16: W | W16: L
A17: 15 | B17: Rodrigo Silva | C17: Rodrigo | D17: =+COUNTA(L17:AD17) -> 5 | E17: =+COUNTIF(L17:AD17,"W") -> 2 | F17: =+COUNTIF(L17:AD17,"L") -> 3 | G17: =E17/D17 -> 0.4 | H17: =VLOOKUP(D17,$B$42:$C$60,2,FALSE) -> 0.26315789 | I17: =+E17/D17 -> 0.4 | J17: =I17*H17 -> 0.10526316 | M17: L | Q17: W | V17: L | W17: W | AD17: L
A18: 16 | B18: Ricardo Campos | C18: Ricardo Campos | D18: =+COUNTA(L18:AD18) -> 1 | E18: =+COUNTIF(L18:AD18,"W") -> 1 | F18: =+COUNTIF(L18:AD18,"L") -> 0 | G18: =E18/D18 -> 1 | H18: =VLOOKUP(D18,$B$42:$C$60,2,FALSE) -> 0.052631579 | I18: =+E18/D18 -> 1 | J18: =I18*H18 -> 0.052631579 | L18: W
A19: 16 | B19: Tiago Capela | C19: Capela Jr | D19: =+COUNTA(L19:AD19) -> 1 | E19: =+COUNTIF(L19:AD19,"W") -> 1 | F19: =+COUNTIF(L19:AD19,"L") -> 0 | G19: =E19/D19 -> 1 | H19: =VLOOKUP(D19,$B$42:$C$60,2,FALSE) -> 0.052631579 | I19: =+E19/D19 -> 1 | J19: =I19*H19 -> 0.052631579 | N19: W
A20: 16 | B20: Carlos Sousa | C20: Carlinhos | D20: =+COUNTA(L20:AD20) -> 1 | E20: =+COUNTIF(L20:AD20,"W") -> 1 | F20: =+COUNTIF(L20:AD20,"L") -> 0 | G20: =E20/D20 -> 1 | H20: =VLOOKUP(D20,$B$42:$C$60,2,FALSE) -> 0.052631579 | I20: =+E20/D20 -> 1 | J20: =I20*H20 -> 0.052631579 | N20: W
A21: 16 | B21: Rodrigo Lima | C21: Rodri Lima | D21: =+COUNTA(L21:AD21) -> 1 | E21: =+COUNTIF(L21:AD21,"W") -> 1 | F21: =+COUNTIF(L21:AD21,"L") -> 0 | G21: =E21/D21 -> 1 | H21: =VLOOKUP(D21,$B$42:$C$60,2,FALSE) -> 0.052631579 | I21: =+E21/D21 -> 1 | J21: =I21*H21 -> 0.052631579 | N21: W
A22: 16 | B22: Rui Dimas | C22: Dimas | D22: =+COUNTA(L22:AD22) -> 1 | E22: =+COUNTIF(L22:AD22,"W") -> 1 | F22: =+COUNTIF(L22:AD22,"L") -> 0 | G22: =E22/D22 -> 1 | H22: =VLOOKUP(D22,$B$42:$C$60,2,FALSE) -> 0.052631579 | I22: =+E22/D22 -> 1 | J22: =I22*H22 -> 0.052631579 | Q22: W
A23: 16 | B23: Simão Mendes | C23: Simão | D23: =+COUNTA(L23:AD23) -> 1 | E23: =+COUNTIF(L23:AD23,"W") -> 1 | F23: =+COUNTIF(L23:AD23,"L") -> 0 | G23: =E23/D23 -> 1 | H23: =VLOOKUP(D23,$B$42:$C$60,2,FALSE) -> 0.052631579 | I23: =+E23/D23 -> 1 | J23: =I23*H23 -> 0.052631579 | AB23: W
A24: 22 | B24: Diogo Azevedo | C24: Dipi | D24: =+COUNTA(L24:AD24) -> 2 | E24: =+COUNTIF(L24:AD24,"W") -> 1 | F24: =+COUNTIF(L24:AD24,"L") -> 1 | G24: =E24/D24 -> 0.5 | H24: =VLOOKUP(D24,$B$42:$C$60,2,FALSE) -> 0.10526316 | I24: =+E24/D24 -> 0.5 | J24: =I24*H24 -> 0.052631579 | L24: W | M24: L
A25: 22 | B25: Bruno Cunha | C25: Bruno Cunha | D25: =+COUNTA(L25:AD25) -> 2 | E25: =+COUNTIF(L25:AD25,"W") -> 1 | F25: =+COUNTIF(L25:AD25,"L") -> 1 | G25: =E25/D25 -> 0.5 | H25: =VLOOKUP(D25,$B$42:$C$60,2,FALSE) -> 0.10526316 | I25: =+E25/D25 -> 0.5 | J25: =I25*H25 -> 0.052631579 | O25: L | AD25: W
A26: 24 | B26: Diogo Castro | C26: Castro | D26: =+COUNTA(L26:AD26) -> 3 | E26: =+COUNTIF(L26:AD26,"W") -> 1 | F26: =+COUNTIF(L26:AD26,"L") -> 2 | G26: =E26/D26 -> 0.33333333 | H26: =VLOOKUP(D26,$B$42:$C$60,2,FALSE) -> 0.15789474 | I26: =+E26/D26 -> 0.33333333 | J26: =I26*H26 -> 0.052631579 | R26: W | Y26: L | AA26: L
A27: 25 | B27: Tiago Filipe | C27: Tigas | D27: =+COUNTA(L27:AD27) -> 4 | E27: =+COUNTIF(L27:AD27,"W") -> 1 | F27: =+COUNTIF(L27:AD27,"L") -> 3 | G27: =E27/D27 -> 0.25 | H27: =VLOOKUP(D27,$B$42:$C$60,2,FALSE) -> 0.21052632 | I27: =+E27/D27 -> 0.25 | J27: =I27*H27 -> 0.052631579 | N27: L | O27: L | P27: L | Q27: W
A28: 25 | B28: Tiago Cabreira | C28: Cabreira | D28: =+COUNTA(L28:AD28) -> 4 | E28: =+COUNTIF(L28:AD28,"W") -> 1 | F28: =+COUNTIF(L28:AD28,"L") -> 3 | G28: =E28/D28 -> 0.25 | H28: =VLOOKUP(D28,$B$42:$C$60,2,FALSE) -> 0.21052632 | I28: =+E28/D28 -> 0.25 | J28: =I28*H28 -> 0.052631579 | T28: L | U28: W | X28: L | Z28: L
A29: 25 | B29: Diogo Souto | C29: Souto | D29: =+COUNTA(L29:AD29) -> 4 | E29: =+COUNTIF(L29:AD29,"W") -> 1 | F29: =+COUNTIF(L29:AD29,"L") -> 3 | G29: =E29/D29 -> 0.25 | H29: =VLOOKUP(D29,$B$42:$C$60,2,FALSE) -> 0.21052632 | I29: =+E29/D29 -> 0.25 | J29: =I29*H29 -> 0.052631579 | L29: L | N29: L | AA29: W | AC29: L
A30: 28 | B30: António Pinto | C30: Pinto | D30: =+COUNTA(L30:AD30) -> 5 | E30: =+COUNTIF(L30:AD30,"W") -> 1 | F30: =+COUNTIF(L30:AD30,"L") -> 4 | G30: =E30/D30 -> 0.2 | H30: =VLOOKUP(D30,$B$42:$C$60,2,FALSE) -> 0.26315789 | I30: =+E30/D30 -> 0.2 | J30: =I30*H30 -> 0.052631579 | O30: L | Q30: L | R30: W | T30: L | U30: L
A31: 29 | B31: Marco Miguel | C31: Marquinho | D31: =+COUNTA(L31:AD31) -> 1 | E31: =+COUNTIF(L31:AD31,"W") -> 0 | F31: =+COUNTIF(L31:AD31,"L") -> 1 | G31: =E31/D31 -> 0 | H31: =VLOOKUP(D31,$B$42:$C$60,2,FALSE) -> 0.052631579 | I31: =+E31/D31 -> 0 | J31: =I31*H31 -> 0 | Y31: L
A32: 29 | B32: Leonardo Domingos | C32: Leo | D32: =+COUNTA(L32:AD32) -> 1 | E32: =+COUNTIF(L32:AD32,"W") -> 0 | F32: =+COUNTIF(L32:AD32,"L") -> 1 | G32: =E32/D32 -> 0 | H32: =VLOOKUP(D32,$B$42:$C$60,2,FALSE) -> 0.052631579 | I32: =+E32/D32 -> 0 | J32: =I32*H32 -> 0 | L32: L
A33: 29 | B33: Ricardo Nunes | C33: Nunes | D33: =+COUNTA(L33:AD33) -> 1 | E33: =+COUNTIF(L33:AD33,"W") -> 0 | F33: =+COUNTIF(L33:AD33,"L") -> 1 | G33: =E33/D33 -> 0 | H33: =VLOOKUP(D33,$B$42:$C$60,2,FALSE) -> 0.052631579 | I33: =+E33/D33 -> 0 | J33: =I33*H33 -> 0 | AA33: L
A34: 29 | B34: Francisco Santos | C34: Xico Santos | D34: =+COUNTA(L34:AD34) -> 1 | E34: =+COUNTIF(L34:AD34,"W") -> 0 | F34: =+COUNTIF(L34:AD34,"L") -> 1 | G34: =E34/D34 -> 0 | H34: =VLOOKUP(D34,$B$42:$C$60,2,FALSE) -> 0.052631579 | I34: =+E34/D34 -> 0 | J34: =I34*H34 -> 0 | N34: L
A35: 29 | B35: Guilherme Macedo | C35: Macedo | D35: =+COUNTA(L35:AD35) -> 1 | E35: =+COUNTIF(L35:AD35,"W") -> 0 | F35: =+COUNTIF(L35:AD35,"L") -> 1 | G35: =E35/D35 -> 0 | H35: =VLOOKUP(D35,$B$42:$C$60,2,FALSE) -> 0.052631579 | I35: =+E35/D35 -> 0 | J35: =I35*H35 -> 0 | AB35: L
A36: 34 | B36: Pedro Gomes | C36: Jonas | D36: =+COUNTA(L36:AD36) -> 2 | E36: =+COUNTIF(L36:AD36,"W") -> 0 | F36: =+COUNTIF(L36:AD36,"L") -> 2 | G36: =E36/D36 -> 0 | H36: =VLOOKUP(D36,$B$42:$C$60,2,FALSE) -> 0.10526316 | I36: =+E36/D36 -> 0 | J36: =I36*H36 -> 0 | T36: L | X36: L
A37: 35 | B37: Diogo Duarte | C37: Insua | D37: =+COUNTA(L37:AD37) -> 4 | E37: =+COUNTIF(L37:AD37,"W") -> 0 | F37: =+COUNTIF(L37:AD37,"L") -> 4 | G37: =E37/D37 -> 0 | H37: =VLOOKUP(D37,$B$42:$C$60,2,FALSE) -> 0.21052632 | I37: =+E37/D37 -> 0 | J37: =I37*H37 -> 0 | L37: L | M37: L | N37: L | P37: L
D38: =SUM(D3:D37) -> 190 | E38: =SUM(E3:E37) -> 95 | F38: =SUM(F3:F37) -> 95
B39: Numero de semanas | D39: =D38/10 -> 19
B41: Fator | G41: {=TRANSPOSE(F42:F49)} -> Capela | H41: Quim | I41: Vieira | J41: Campos | K41: Gui Moura | L41: Alex | M41: Renato | N41: Edu | Q41: 0.8-1.0 | S41: 45908 | T41: Vieira x Campos | X41: Maior streak de vitórias | AA41: Canito, Quim e Raul | AC41: 5
...

Sheet UCL SS 3ed
A1: Retorta League SS 3ed (10/03/2026 a 14/07/2026)
A2: Ranking | B2: Jogadores | C2: Alcunha | D2: Jogos | E2: Vitórias | F2: Derrotas | G2: Win Rate | H2: Fator | I2: Média base | J2: Média ponderada | L2: 46091 | M2: =+L2+7 -> 46098 | N2: =+M2+7 -> 46105 | O2: =+N2+7 -> 46112 | P2: =+O2+7 -> 46119 | Q2: =+P2+7 -> 46126 | R2: =+Q2+7 -> 46133 | S2: =+R2+7 -> 46140 | T2: =+S2+7 -> 46147 | ... AD2: =+AC2+7 -> 46217
A3: 1 | B3: Francisco Campos | C3: Campos | D3: =+COUNTA(L3:AD3) -> 8 | E3: =+COUNTIF(L3:AD3,"W") -> 7 | F3: =+COUNTIF(L3:AD3,"L") -> 1 | G3: =E3/D3 -> 0.875 | H3: =VLOOKUP(D3,$B$29:$C$47,2,FALSE) -> 0.66666667 | I3: =+E3/D3 -> 0.875 | J3: =I3*H3 -> 0.58333333 | O3: W | P3: W | Q3: W | R3: W | S3: L | T3: W | U3: W | W3: W
A4: 2 | B4: Rodrigo Silva | C4: Rodrigo | D4: =+COUNTA(L4:AD4) -> 10 | E4: =+COUNTIF(L4:AD4,"W") -> 7 | F4: =+COUNTIF(L4:AD4,"L") -> 3 | G4: =E4/D4 -> 0.7 | H4: =VLOOKUP(D4,$B$29:$C$47,2,FALSE) -> 0.83333333 | I4: =+E4/D4 -> 0.7 | J4: =I4*H4 -> 0.58333333 | L4: L | M4: L | N4: W | O4: L | P4: W | Q4: W | R4: W | S4: W | T4: W | W4: W
A5: 3 | B5: João Capela | C5: Capela | D5: =+COUNTA(L5:AD5) -> 11 | E5: =+COUNTIF(L5:AD5,"W") -> 7 | F5: =+COUNTIF(L5:AD5,"L") -> 4 | G5: =E5/D5 -> 0.63636364 | H5: =VLOOKUP(D5,$B$29:$C$47,2,FALSE) -> 0.91666667 | I5: =+E5/D5 -> 0.63636364 | J5: =I5*H5 -> 0.58333333 | L5: W | M5: W | N5: L | O5: W | P5: W | Q5: L | R5: W | T5: L | U5: W | V5: W | W5: L
A6: 4 | B6: Raul Trocado | C6: Trocado | D6: =+COUNTA(L6:AD6) -> 11 | E6: =+COUNTIF(L6:AD6,"W") -> 6 | F6: =+COUNTIF(L6:AD6,"L") -> 5 | G6: =E6/D6 -> 0.54545455 | H6: =VLOOKUP(D6,$B$29:$C$47,2,FALSE) -> 0.91666667 | I6: =+E6/D6 -> 0.54545455 | J6: =I6*H6 -> 0.5 | M6: W | N6: L | O6: W | P6: L | Q6: L | R6: W | S6: W | T6: L | U6: W | V6: W | W6: L
A7: 5 | B7: João Santos | C7: Jorginho | D7: =+COUNTA(L7:AD7) -> 7 | E7: =+COUNTIF(L7:AD7,"W") -> 5 | F7: =+COUNTIF(L7:AD7,"L") -> 2 | G7: =E7/D7 -> 0.71428571 | H7: =VLOOKUP(D7,$B$29:$C$47,2,FALSE) -> 0.58333333 | I7: =+E7/D7 -> 0.71428571 | J7: =I7*H7 -> 0.41666667 | L7: W | Q7: W | R7: W | S7: W | U7: L | V7: W | W7: L
A8: 6 | B8: José Miguel Ferreira | C8: Zé Miguel | D8: =+COUNTA(L8:AD8) -> 9 | E8: =+COUNTIF(L8:AD8,"W") -> 5 | F8: =+COUNTIF(L8:AD8,"L") -> 4 | G8: =E8/D8 -> 0.55555556 | H8: =VLOOKUP(D8,$B$29:$C$47,2,FALSE) -> 0.75 | I8: =+E8/D8 -> 0.55555556 | J8: =I8*H8 -> 0.41666667 | N8: W | O8: W | Q8: L | R8: L | S8: L | T8: W | U8: W | V8: L | W8: W
A9: 7 | B9: Joaquim Torrão | C9: Quim | D9: =+COUNTA(L9:AD9) -> 10 | E9: =+COUNTIF(L9:AD9,"W") -> 4 | F9: =+COUNTIF(L9:AD9,"L") -> 6 | G9: =E9/D9 -> 0.4 | H9: =VLOOKUP(D9,$B$29:$C$47,2,FALSE) -> 0.83333333 | I9: =+E9/D9 -> 0.4 | J9: =I9*H9 -> 0.33333333 | L9: L | M9: W | N9: L | O9: L | P9: L | Q9: L | R9: L | S9: W | T9: W | W9: W
A10: 8 | B10: Renato Pereira | C10: Renato | D10: =+COUNTA(L10:AD10) -> 11 | E10: =+COUNTIF(L10:AD10,"W") -> 4 | F10: =+COUNTIF(L10:AD10,"L") -> 7 | G10: =E10/D10 -> 0.36363636 | H10: =VLOOKUP(D10,$B$29:$C$47,2,FALSE) -> 0.91666667 | I10: =+E10/D10 -> 0.36363636 | J10: =I10*H10 -> 0.33333333 | L10: W | M10: L | N10: W | O10: L | Q10: W | R10: L | S10: L | T10: L | U10: L | V10: W | W10: L
A11: 9 | B11: Pedro Vieira | C11: Vieira | D11: =+COUNTA(L11:AD11) -> 8 | E11: =+COUNTIF(L11:AD11,"W") -> 3 | F11: =+COUNTIF(L11:AD11,"L") -> 5 | G11: =E11/D11 -> 0.375 | H11: =VLOOKUP(D11,$B$29:$C$47,2,FALSE) -> 0.66666667 | I11: =+E11/D11 -> 0.375 | J11: =I11*H11 -> 0.25 | L11: W | M11: W | O11: L | P11: L | R11: L | S11: W | T11: L | V11: L
A12: 10 | B12: Guilherme Moura | C12: Gui Moura | D12: =+COUNTA(L12:AD12) -> 9 | E12: =+COUNTIF(L12:AD12,"W") -> 3 | F12: =+COUNTIF(L12:AD12,"L") -> 6 | G12: =E12/D12 -> 0.33333333 | H12: =VLOOKUP(D12,$B$29:$C$47,2,FALSE) -> 0.75 | I12: =+E12/D12 -> 0.33333333 | J12: =I12*H12 -> 0.25 | L12: L | M12: L | N12: W | O12: L | P12: L | Q12: W | R12: L | T12: W | U12: L
A13: 11 | B13: João Órfão | C13: Órfão | D13: =+COUNTA(L13:AD13) -> 4 | E13: =+COUNTIF(L13:AD13,"W") -> 2 | F13: =+COUNTIF(L13:AD13,"L") -> 2 | G13: =E13/D13 -> 0.5 | H13: =VLOOKUP(D13,$B$29:$C$47,2,FALSE) -> 0.33333333 | I13: =+E13/D13 -> 0.5 | J13: =I13*H13 -> 0.16666667 | S13: L | U13: W | V13: L | W13: W
A14: 12 | B14: Eduardo Maia | C14: Edu | D14: =+COUNTA(L14:AD14) -> 9 | E14: =+COUNTIF(L14:AD14,"W") -> 2 | F14: =+COUNTIF(L14:AD14,"L") -> 7 | G14: =E14/D14 -> 0.22222222 | H14: =VLOOKUP(D14,$B$29:$C$47,2,FALSE) -> 0.75 | I14: =+E14/D14 -> 0.22222222 | J14: =I14*H14 -> 0.16666667 | M14: L | O14: W | P14: W | Q14: L | S14: L | T14: L | U14: L | V14: L | W14: L
A15: 13 | B15: Diogo Castro | C15: Castro | D15: =+COUNTA(L15:AD15) -> 1 | E15: =+COUNTIF(L15:AD15,"W") -> 1 | F15: =+COUNTIF(L15:AD15,"L") -> 0 | G15: =E15/D15 -> 1 | H15: =VLOOKUP(D15,$B$29:$C$47,2,FALSE) -> 0.083333333 | I15: =+E15/D15 -> 1 | J15: =I15*H15 -> 0.083333333 | N15: W
A16: 13 | B16: Vítor Leite | C16: Vítor | D16: =+COUNTA(L16:AD16) -> 1 | E16: =+COUNTIF(L16:AD16,"W") -> 1 | F16: =+COUNTIF(L16:AD16,"L") -> 0 | G16: =E16/D16 -> 1 | H16: =VLOOKUP(D16,$B$29:$C$47,2,FALSE) -> 0.083333333 | I16: =+E16/D16 -> 1 | J16: =I16*H16 -> 0.083333333 | V16: W
A17: 15 | B17: Diogo Souto | C17: Souto | D17: =+COUNTA(L17:AD17) -> 2 | E17: =+COUNTIF(L17:AD17,"W") -> 1 | F17: =+COUNTIF(L17:AD17,"L") -> 1 | G17: =E17/D17 -> 0.5 | H17: =VLOOKUP(D17,$B$29:$C$47,2,FALSE) -> 0.16666667 | I17: =+E17/D17 -> 0.5 | J17: =I17*H17 -> 0.083333333 | L17: W | N17: L
A18: 15 | B18: João Silva | C18: Alex | D18: =+COUNTA(L18:AD18) -> 2 | E18: =+COUNTIF(L18:AD18,"W") -> 1 | F18: =+COUNTIF(L18:AD18,"L") -> 1 | G18: =E18/D18 -> 0.5 | H18: =VLOOKUP(D18,$B$29:$C$47,2,FALSE) -> 0.16666667 | I18: =+E18/D18 -> 0.5 | J18: =I18*H18 -> 0.083333333 | L18: L | M18: W
A19: 15 | B19: Gonçalo Silva | C19: Anke | D19: =+COUNTA(L19:AD19) -> 2 | E19: =+COUNTIF(L19:AD19,"W") -> 1 | F19: =+COUNTIF(L19:AD19,"L") -> 1 | G19: =E19/D19 -> 0.5 | H19: =VLOOKUP(D19,$B$29:$C$47,2,FALSE) -> 0.16666667 | I19: =+E19/D19 -> 0.5 | J19: =I19*H19 -> 0.083333333 | N19: L | P19: W
A20: 18 | B20: Martim Pereira | C20: Martim | D20: =+COUNTA(L20:AD20) -> 1 | E20: =+COUNTIF(L20:AD20,"W") -> 0 | F20: =+COUNTIF(L20:AD20,"L") -> 1 | G20: =E20/D20 -> 0 | H20: =VLOOKUP(D20,$B$29:$C$47,2,FALSE) -> 0.083333333 | I20: =+E20/D20 -> 0 | J20: =I20*H20 -> 0 | M20: L
A21: 18 | B21: Jorge Rajão | C21: Rajão | D21: =+COUNTA(L21:AD21) -> 1 | E21: =+COUNTIF(L21:AD21,"W") -> 0 | F21: =+COUNTIF(L21:AD21,"L") -> 1 | G21: =E21/D21 -> 0 | H21: =VLOOKUP(D21,$B$29:$C$47,2,FALSE) -> 0.083333333 | I21: =+E21/D21 -> 0 | J21: =I21*H21 -> 0 | P21: L
A22: 18 | B22: Dinis Pontes | C22: Trator | D22: =+COUNTA(L22:AD22) -> 1 | E22: =+COUNTIF(L22:AD22,"W") -> 0 | F22: =+COUNTIF(L22:AD22,"L") -> 1 | G22: =E22/D22 -> 0 | H22: =VLOOKUP(D22,$B$29:$C$47,2,FALSE) -> 0.083333333 | I22: =+E22/D22 -> 0 | J22: =I22*H22 -> 0 | U22: L
A23: 18 | B23: Diogo Duarte | C23: Insua | D23: =+COUNTA(L23:AD23) -> 1 | E23: =+COUNTIF(L23:AD23,"W") -> 0 | F23: =+COUNTIF(L23:AD23,"L") -> 1 | G23: =E23/D23 -> 0 | H23: =VLOOKUP(D23,$B$29:$C$47,2,FALSE) -> 0.083333333 | I23: =+E23/D23 -> 0 | J23: =I23*H23 -> 0 | V23: L
A24: 18 | B24: Leandro Terroso | C24: Zé Li | D24: =+COUNTA(L24:AD24) -> 1 | E24: =+COUNTIF(L24:AD24,"W") -> 0 | F24: =+COUNTIF(L24:AD24,"L") -> 1 | G24: =E24/D24 -> 0 | H24: =VLOOKUP(D24,$B$29:$C$47,2,FALSE) -> 0.083333333 | I24: =+E24/D24 -> 0 | J24: =I24*H24 -> 0 | L24: L
D25: =SUM(D3:D24) -> 120 | E25: =SUM(E3:E24) -> 60 | F25: =SUM(F3:F24) -> 60
B26: Numero de semanas | D26: =D25/10 -> 12
B28: Fator | G28: 0.8-1.0 | X28: Maior streak de vitórias | AA28: Rodri | AC28: 6
B29: 1 | C29: =B29/$D$26 -> 0.083333333 | G29: 0.6-0.8 | X29: Streak de vitórias atual | AA29: Rodri | AC29: 6
B30: 2 | C30: =B30/$D$26 -> 0.16666667 | G30: 0.4-0.6 | X30: Maior streak de derrotas | AA30: Edu | AC30: 6
B31: 3 | C31: =B31/$D$26 -> 0.25 | G31: 0.2-0.4 | X31: Streak de derrotas atual | AA31: Edu | AC31: 6
B32: 4 | C32: =B32/$D$26 -> 0.33333333 | G32: 0.0-0.2
B33: 5 | C33: =B33/$D$26 -> 0.41666667 | X33: Presenças
B34: 6 | C34: =B34/$D$26 -> 0.5 | X34: Top10 | Y34: Nome | Z34: Jogos | AA34: Restantes | AB34: Nome | AC34: Jogos
B35: 7 | C35: =B35/$D$26 -> 0.58333333 | X35: 1 | Y35: Capela | Z35: =+VLOOKUP(Y35,$C$2:$D$24,2,0) -> 11 | AA35: 11 | AB35: Jorginho | AC35: =+VLOOKUP(AB35,$C$2:$D$24,2,0) -> 7
B36: 8 | C36: =B36/$D$26 -> 0.66666667 | X36: 1 | Y36: Renato | Z36: =+VLOOKUP(Y36,$C$2:$D$24,2,0) -> 11 | AA36: 12 | AB36: Órfão | AC36: =+VLOOKUP(AB36,$C$2:$D$24,2,0) -> 4
B37: 9 | C37: =B37/$D$26 -> 0.75 | X37: 1 | Y37: Trocado | Z37: =+VLOOKUP(Y37,$C$2:$D$24,2,0) -> 11 | AA37: 13 | AB37: Souto | AC37: =+VLOOKUP(AB37,$C$2:$D$24,2,0) -> 2
B38: 10 | C38: =B38/$D$26 -> 0.83333333 | X38: 4 | Y38: Rodrigo | Z38: =+VLOOKUP(Y38,$C$2:$D$24,2,0) -> 10 | AA38: 13 | AB38: Alex | AC38: =+VLOOKUP(AB38,$C$2:$D$24,2,0) -> 2
B39: 11 | C39: =B39/$D$26 -> 0.91666667 | X39: 4 | Y39: Quim | Z39: =+VLOOKUP(Y39,$C$2:$D$24,2,0) -> 10 | AA39: 13 | AB39: Anke | AC39: =+VLOOKUP(AB39,$C$2:$D$24,2,0) -> 2
B40: 12 | C40: =B40/$D$26 -> 1 | X40: 6 | Y40: Gui Moura | Z40: =+VLOOKUP(Y40,$C$2:$D$24,2,0) -> 9 | AA40: 16 | AB40: Rajão | AC40: =+VLOOKUP(AB40,$C$2:$D$24,2,0) -> 1
B41: 13 | C41: =B41/$D$26 -> 1.0833333 | X41: 6 | Y41: Zé Miguel | Z41: =+VLOOKUP(Y41,$C$2:$D$24,2,0) -> 9 | AA41: 16 | AB41: Castro | AC41: =+VLOOKUP(AB41,$C$2:$D$24,2,0) -> 1
...

Sheet All-Time
B2: Retorta League (desde 18/03/2024)
B3: Ranking por | E3: Summer Season (18/03 a 29/07) | I3: Winter Season (05/09 a 28/01) | M3: Summer Season 2ed (06/03 a 07/07) | Q3: Winter Season 2ed (08/09 a 19/01) | U3: Summer Season 3ed (10/03 a 14/07) | Y3: TOTAL
B4: Presenças | C4: Jogadores | D4: Alcunha | E4: Jogos | F4: Vitórias | G4: Derrotas | H4: Win Rate | I4: Jogos | J4: Vitórias | K4: Derrotas | L4: Win Rate | M4: Jogos | N4: Vitórias | O4: Derrotas | P4: Win Rate | Q4: Jogos | R4: Vitórias | S4: Derrotas | T4: Win Rate | U4: Jogos | V4: Vitórias | W4: Derrotas | X4: Win Rate | Y4: Jogos T | Z4: Vitórias | AA4: Derrotas | AB4: Win Rate | AC4: Notas
B5: 1 | C5: João Capela | D5: Capela | E5: =IFERROR((VLOOKUP(D5,'UCL SS'!$C$3:$D$31,2,FALSE)),0) -> 19 | F5: =IFERROR(VLOOKUP(D5,'UCL SS'!$C$3:$E$31,3,FALSE),0) -> 13 | G5: =IFERROR(VLOOKUP(D5,'UCL SS'!$C$3:$F$31,4,FALSE),0) -> 6 | H5: =IFERROR(F5/E5,0) -> 0.68421053 | I5: =IFERROR(VLOOKUP(D5,'UCL WS'!$C$3:$F$35,2,FALSE),0) -> 18 | J5: =IFERROR(VLOOKUP(D5,'UCL WS'!$C$3:$F$35,3,FALSE),0) -> 13 | K5: =IFERROR(VLOOKUP(D5,'UCL WS'!$C$3:$F$35,4,FALSE),0) -> 5 | L5: =IFERROR(J5/I5,0) -> 0.72222222 | M5: =IFERROR(VLOOKUP(D5,'UCL SS 2ed'!$C$3:$F$50,2,FALSE),0) -> 18 | N5: =IFERROR(VLOOKUP(D5,'UCL SS 2ed'!$C$3:$F$50,3,FALSE),0) -> 9 | O5: =IFERROR(VLOOKUP(D5,'UCL SS 2ed'!$C$3:$F$50,4,FALSE),0) -> 9 | P5: =IFERROR(N5/M5,0) -> 0.5 | Q5: =+_xlfn.XLOOKUP(D5,'UCL WS 2ed'!$C$3:$C$37,'UCL WS 2ed'!$D$3:$D$37,0,0) -> 18 | R5: =+_xlfn.XLOOKUP(D5,'UCL WS 2ed'!$C$3:$C$37,'UCL WS 2ed'!$E$3:$E$37,0,0) -> 10 | S5: =+_xlfn.XLOOKUP(D5,'UCL WS 2ed'!$C$3:$C$37,'UCL WS 2ed'!$F$3:$F$37,0) -> 8 | T5: =IFERROR(R5/Q5,0) -> 0.55555556 | U5: =IFERROR(VLOOKUP(D5,'UCL SS 3ed'!$C$3:$F$24,2,FALSE),0) -> 11 | V5: =IFERROR(VLOOKUP(D5,'UCL SS 3ed'!$C$3:$F$24,3,FALSE),0) -> 7 | W5: =IFERROR(VLOOKUP(D5,'UCL SS 3ed'!$C$3:$F$24,4,FALSE),0) -> 4 | X5: =IFERROR(V5/U5,0) -> 0.63636364 | Y5: =E5+I5+M5+Q5+U5 -> 84 | Z5: =F5+J5+N5+R5+V5 -> 52 | AA5: =G5+K5+O5+S5+W5 -> 32 | AB5: =Z5/Y5 -> 0.61904762
B6: 2 | C6: Joaquim Torrão | D6: Quim | E6: =IFERROR((VLOOKUP(D6,'UCL SS'!$C$3:$D$31,2,FALSE)),0) -> 19 | F6: =IFERROR(VLOOKUP(D6,'UCL SS'!$C$3:$E$31,3,FALSE),0) -> 8 | G6: =IFERROR(VLOOKUP(D6,'UCL SS'!$C$3:$F$31,4,FALSE),0) -> 11 | H6: =IFERROR(F6/E6,0) -> 0.42105263 | I6: =IFERROR(VLOOKUP(D6,'UCL WS'!$C$3:$F$35,2,FALSE),0) -> 15 | J6: =IFERROR(VLOOKUP(D6,'UCL WS'!$C$3:$F$35,3,FALSE),0) -> 8 | K6: =IFERROR(VLOOKUP(D6,'UCL WS'!$C$3:$F$35,4,FALSE),0) -> 7 | L6: =IFERROR(J6/I6,0) -> 0.53333333 | M6: =IFERROR(VLOOKUP(D6,'UCL SS 2ed'!$C$3:$F$50,2,FALSE),0) -> 19 | N6: =IFERROR(VLOOKUP(D6,'UCL SS 2ed'!$C$3:$F$50,3,FALSE),0) -> 12 | O6: =IFERROR(VLOOKUP(D6,'UCL SS 2ed'!$C$3:$F$50,4,FALSE),0) -> 7 | P6: =IFERROR(N6/M6,0) -> 0.63157895 | Q6: =+_xlfn.XLOOKUP(D6,'UCL WS 2ed'!$C$3:$C$37,'UCL WS 2ed'!$D$3:$D$37,0,0) -> 18 | R6: =+_xlfn.XLOOKUP(D6,'UCL WS 2ed'!$C$3:$C$37,'UCL WS 2ed'!$E$3:$E$37,0,0) -> 12 | S6: =+_xlfn.XLOOKUP(D6,'UCL WS 2ed'!$C$3:$C$37,'UCL WS 2ed'!$F$3:$F$37,0) -> 6 | T6: =IFERROR(R6/Q6,0) -> 0.66666667 | U6: =IFERROR(VLOOKUP(D6,'UCL SS 3ed'!$C$3:$F$24,2,FALSE),0) -> 10 | V6: =IFERROR(VLOOKUP(D6,'UCL SS 3ed'!$C$3:$F$24,3,FALSE),0) -> 4 | W6: =IFERROR(VLOOKUP(D6,'UCL SS 3ed'!$C$3:$F$24,4,FALSE),0) -> 6 | X6: =IFERROR(V6/U6,0) -> 0.4 | Y6: =E6+I6+M6+Q6+U6 -> 81 | Z6: =F6+J6+N6+R6+V6 -> 44 | AA6: =G6+K6+O6+S6+W6 -> 37 | AB6: =Z6/Y6 -> 0.54320988
B7: 3 | C7: Francisco Campos | D7: Campos | E7: =IFERROR((VLOOKUP(D7,'UCL SS'!$C$3:$D$31,2,FALSE)),0) -> 17 | F7: =IFERROR(VLOOKUP(D7,'UCL SS'!$C$3:$E$31,3,FALSE),0) -> 9 | G7: =IFERROR(VLOOKUP(D7,'UCL SS'!$C$3:$F$31,4,FALSE),0) -> 8 | H7: =IFERROR(F7/E7,0) -> 0.52941176 | I7: =IFERROR(VLOOKUP(D7,'UCL WS'!$C$3:$F$35,2,FALSE),0) -> 15 | J7: =IFERROR(VLOOKUP(D7,'UCL WS'!$C$3:$F$35,3,FALSE),0) -> 8 | K7: =IFERROR(VLOOKUP(D7,'UCL WS'!$C$3:$F$35,4,FALSE),0) -> 7 | L7: =IFERROR(J7/I7,0) -> 0.53333333 | M7: =IFERROR(VLOOKUP(D7,'UCL SS 2ed'!$C$3:$F$50,2,FALSE),0) -> 9 | N7: =IFERROR(VLOOKUP(D7,'UCL SS 2ed'!$C$3:$F$50,3,FALSE),0) -> 5 | O7: =IFERROR(VLOOKUP(D7,'UCL SS 2ed'!$C$3:$F$50,4,FALSE),0) -> 4 | P7: =IFERROR(N7/M7,0) -> 0.55555556 | Q7: =+_xlfn.XLOOKUP(D7,'UCL WS 2ed'!$C$3:$C$37,'UCL WS 2ed'!$D$3:$D$37,0,0) -> 14 | R7: =+_xlfn.XLOOKUP(D7,'UCL WS 2ed'!$C$3:$C$37,'UCL WS 2ed'!$E$3:$E$37,0,0) -> 8 | S7: =+_xlfn.XLOOKUP(D7,'UCL WS 2ed'!$C$3:$C$37,'UCL WS 2ed'!$F$3:$F$37,0) -> 6 | T7: =IFERROR(R7/Q7,0) -> 0.57142857 | U7: =IFERROR(VLOOKUP(D7,'UCL SS 3ed'!$C$3:$F$24,2,FALSE),0) -> 8 | V7: =IFERROR(VLOOKUP(D7,'UCL SS 3ed'!$C$3:$F$24,3,FALSE),0) -> 7 | W7: =IFERROR(VLOOKUP(D7,'UCL SS 3ed'!$C$3:$F$24,4,FALSE),0) -> 1 | X7: =IFERROR(V7/U7,0) -> 0.875 | Y7: =E7+I7+M7+Q7+U7 -> 63 | Z7: =F7+J7+N7+R7+V7 -> 37 | AA7: =G7+K7+O7+S7+W7 -> 26 | AB7: =Z7/Y7 -> 0.58730159
B8: 4 | C8: Pedro Vieira | D8: Vieira | E8: =IFERROR((VLOOKUP(D8,'UCL SS'!$C$3:$D$31,2,FALSE)),0) -> 18 | F8: =IFERROR(VLOOKUP(D8,'UCL SS'!$C$3:$E$31,3,FALSE),0) -> 10 | G8: =IFERROR(VLOOKUP(D8,'UCL SS'!$C$3:$F$31,4,FALSE),0) -> 8 | H8: =IFERROR(F8/E8,0) -> 0.55555556 | I8: =IFERROR(VLOOKUP(D8,'UCL WS'!$C$3:$F$35,2,FALSE),0) -> 12 | J8: =IFERROR(VLOOKUP(D8,'UCL WS'!$C$3:$F$35,3,FALSE),0) -> 6 | K8: =IFERROR(VLOOKUP(D8,'UCL WS'!$C$3:$F$35,4,FALSE),0) -> 6 | L8: =IFERROR(J8/I8,0) -> 0.5 | M8: =IFERROR(VLOOKUP(D8,'UCL SS 2ed'!$C$3:$F$50,2,FALSE),0) -> 12 | N8: =IFERROR(VLOOKUP(D8,'UCL SS 2ed'!$C$3:$F$50,3,FALSE),0) -> 6 | O8: =IFERROR(VLOOKUP(D8,'UCL SS 2ed'!$C$3:$F$50,4,FALSE),0) -> 6 | P8: =IFERROR(N8/M8,0) -> 0.5 | Q8: =+_xlfn.XLOOKUP(D8,'UCL WS 2ed'!$C$3:$C$37,'UCL WS 2ed'!$D$3:$D$37,0,0) -> 7 | R8: =+_xlfn.XLOOKUP(D8,'UCL WS 2ed'!$C$3:$C$37,'UCL WS 2ed'!$E$3:$E$37,0,0) -> 4 | S8: =+_xlfn.XLOOKUP(D8,'UCL WS 2ed'!$C$3:$C$37,'UCL WS 2ed'!$F$3:$F$37,0) -> 3 | T8: =IFERROR(R8/Q8,0) -> 0.57142857 | U8: =IFERROR(VLOOKUP(D8,'UCL SS 3ed'!$C$3:$F$24,2,FALSE),0) -> 8 | V8: =IFERROR(VLOOKUP(D8,'UCL SS 3ed'!$C$3:$F$24,3,FALSE),0) -> 3 | W8: =IFERROR(VLOOKUP(D8,'UCL SS 3ed'!$C$3:$F$24,4,FALSE),0) -> 5 | X8: =IFERROR(V8/U8,0) -> 0.375 | Y8: =E8+I8+M8+Q8+U8 -> 57 | Z8: =F8+J8+N8+R8+V8 -> 29 | AA8: =G8+K8+O8+S8+W8 -> 28 | AB8: =Z8/Y8 -> 0.50877193
